Workbook

Sheet Hướng dẫn
A1: QUẢN LÝ QUÁN SỮA — MỖI DANH MỤC MỘT SHEET RIÊNG
A3: Cách thêm dữ liệu mới mà không ảnh hưởng bảng khác
A4: Sheet | B4: Cách sử dụng
A5: Hàng hóa | B5: Thêm nguyên liệu, topping hoặc bao bì vào dòng trống tiếp theo.
A6: Size | B6: Thêm size mới vào dòng trống tiếp theo.
A7: Sản phẩm | B7: Chọn tên topping và size; tên sản phẩm và cost tự tính.
A8: Thiết lập | B8: Điện, nước, overhead, chi phí cố định và khấu hao.
A9: Nhập hàng | B9: Chọn tên hàng, nhập số gói và giá thực tế.
A10: Mẻ sữa | B10: Mỗi mẻ có công thức riêng; thêm nguyên liệu ở bảng chi tiết.
A11: Bán hàng | B11: Chọn sản phẩm và đúng mẻ sữa đã dùng.
A13: Lưu ý
A14: Thao tác | B14: Khuyến nghị
A15: Thêm mục mới | B15: Không cần Insert Row. Chỉ nhập vào dòng trống tiếp theo đã chuẩn bị sẵn.
A16: Tên không trùng | B16: Không đặt hai hàng hóa hoặc hai sản phẩm trùng tên hoàn toàn.
A17: Mã nội bộ | B17: Mã được tạo sẵn hoặc tự sinh; khi vận hành chỉ cần chọn bằng tên.
A19: Sheet | B19: Cách sử dụng
A20: Đầu tư & Tài sản | B20: Nhập máy móc, nồi nấu, bếp, tủ lạnh, xe/quầy và dụng cụ lớn.
A21: Khấu hao | B21: Tổng khấu hao/tháng tự liên kết vào Thiết lập và được phân bổ vào cost mỗi ly.
A22: Tổng quan | B22: Hiển thị tổng vốn đầu tư và tiền mua tài sản trong khoảng ngày đang xem.
A23: Sheet | B23: Cách sử dụng
A24: Bán nhanh | B24: Nhập ngày, tên mẻ, thanh toán và số lượng từng món trên một dòng.
A25: Bán hàng | B25: Tự tách dữ liệu từ Bán nhanh. Không nhập hoặc sửa trực tiếp tại sheet này.
A26: Nhiều mẻ trong ngày | B26: Nhập nhiều dòng cùng ngày; mỗi dòng chọn một mẻ sữa khác nhau.

Sheet Thiết lập
A1: THIẾT LẬP CHI PHÍ
A3: Thông số | B3: Giá trị
A4: Công suất bếp mặc định (kW) | B4: 2
A5: Giá điện (đ/kWh) | B5: 3000
A6: Điện khác mỗi mẻ (đ) | B6: 0
A7: Nước/vệ sinh mỗi mẻ (đ) | B7: 5000
A8: Overhead biến đổi | B8: 0.05
A9: Số ly dự kiến/tháng | B9: 1000
A10: Chi phí cố định/tháng (đ) | B10: 0
A11: Khấu hao/tháng từ tài sản (đ) | B11: ='Đầu tư & Tài sản'!$B$208 -> 91363.889
A12: Phân bổ cố định + khấu hao/ly (đ) | B12: =IFERROR((B10+B11)/B9,0) -> 91.363889
A13: Ghi chú | B13: Điện/nước có thể sửa riêng ở từng mẻ
A14: Liên kết tài sản | B14: Tự động
A15: Luồng công thức | B15: Đầu tư & Tài sản → Thiết lập → Sản phẩm/Bán hàng/Tổng quan

Sheet Đầu tư & Tài sản
A1: ĐẦU TƯ BAN ĐẦU & TÀI SẢN KHẤU HAO
A2: Nhập máy móc, nồi nấu, bếp, tủ lạnh, xe/quầy và dụng cụ lớn tại đây. Tổng khấu hao/tháng sẽ tự liên kết sang Thiết lập và cost mỗi ly. | N2: Nhóm tài sản | O2: Kích hoạt
A3: Ngày mua | B3: Tên tài sản | C3: Nhóm tài sản | D3: Số lượng | E3: Đơn giá (đ) | F3: Tổng tiền (đ) | G3: Giá trị còn lại (đ) | H3: Thời gian sử dụng (tháng) | I3: Khấu hao/tháng (đ) | J3: Kích hoạt | K3: Ghi chú | L3: Mã nội bộ | N3: Máy móc | O3: Có
A4: 46224 | B4: Vá múc canh | C4: Dụng cụ lớn | D4: 1 | E4: 120000 | F4: =IF(OR(B4="",D4="",E4=""),0,D4*E4) -> 120000 | G4: 0 | H4: 36 | I4: =IF(OR(B4="",J4<>"Có"),0,IFERROR(MAX(0,(F4-G4)/H4),0)) -> 3333.3333 | J4: Có | L4: =IF(B4="","","TS-"&TEXT(ROW()-3,"000")) -> TS-001 | N4: Dụng cụ lớn | O4: Không
A5: 46224 | B5: Xô đá giữ nhiệt | C5: Cơ sở vật chất | D5: 2 | E5: 185000 | F5: =IF(OR(B5="",D5="",E5=""),0,D5*E5) -> 370000 | G5: 0 | H5: 36 | I5: =IF(OR(B5="",J5<>"Có"),0,IFERROR(MAX(0,(F5-G5)/H5),0)) -> 10277.778 | J5: Có | L5: =IF(B5="","","TS-"&TEXT(ROW()-3,"000")) -> TS-002 | N5: Cơ sở vật chất
A6: 46224 | B6: Khay làm đá nhỏ | C6: Cơ sở vật chất | D6: 5 | E6: 20000 | F6: =IF(OR(B6="",D6="",E6=""),0,D6*E6) -> 100000 | G6: 0 | H6: 36 | I6: =IF(OR(B6="",J6<>"Có"),0,IFERROR(MAX(0,(F6-G6)/H6),0)) -> 2777.7778 | J6: Có | L6: =IF(B6="","","TS-"&TEXT(ROW()-3,"000")) -> TS-003 | N6: Khác
A7: 46223 | B7: Máy bào đá / máy xay | C7: Máy móc | D7: 1 | E7: 682200 | F7: =IF(OR(B7="",D7="",E7=""),0,D7*E7) -> 682200 | G7: 0 | H7: 12 | I7: =IF(OR(B7="",J7<>"Có"),0,IFERROR(MAX(0,(F7-G7)/H7),0)) -> 56850 | J7: Có | L7: =IF(B7="","","TS-"&TEXT(ROW()-3,"000")) -> TS-004
A8: 46223 | B8: Bàn inox | C8: Cơ sở vật chất | D8: 1 | E8: 420000 | F8: =IF(OR(B8="",D8="",E8=""),0,D8*E8) -> 420000 | G8: 0 | H8: 24 | I8: =IF(OR(B8="",J8<>"Có"),0,IFERROR(MAX(0,(F8-G8)/H8),0)) -> 17500 | J8: Có | L8: =IF(B8="","","TS-"&TEXT(ROW()-3,"000")) -> TS-005
A9: 46225 | B9: Hũ nhựa topping | C9: Cơ sở vật chất | D9: 2 | E9: 7500 | F9: =IF(OR(B9="",D9="",E9=""),0,D9*E9) -> 15000 | G9: 0 | H9: 24 | I9: =IF(OR(B9="",J9<>"Có"),0,IFERROR(MAX(0,(F9-G9)/H9),0)) -> 625 | J9: Có | L9: =IF(B9="","","TS-"&TEXT(ROW()-3,"000")) -> TS-006
A10: 46225 | B10: Kệ đựng ly | C10: Cơ sở vật chất | D10: 1 | E10: 120000 | F10: =IF(OR(B10="",D10="",E10=""),0,D10*E10) -> 120000 | H10: 60 | I10: =IF(OR(B10="",J10<>"Có"),0,IFERROR(MAX(0,(F10-G10)/H10),0)) -> 0 | L10: =IF(B10="","","TS-"&TEXT(ROW()-3,"000")) -> TS-007
A11: 46225 | B11: In bảng chỉ đường | C11: Cơ sở vật chất | D11: 2 | E11: 50000 | F11: =IF(OR(B11="",D11="",E11=""),0,D11*E11) -> 100000 | H11: 24 | I11: =IF(OR(B11="",J11<>"Có"),0,IFERROR(MAX(0,(F11-G11)/H11),0)) -> 0 | L11: =IF(B11="","","TS-"&TEXT(ROW()-3,"000")) -> TS-008
A12: 46224 | B12: In Bảng Quảng Cáo | C12: Cơ sở vật chất | D12: 1 | E12: 150000 | F12: =IF(OR(B12="",D12="",E12=""),0,D12*E12) -> 150000 | H12: 24 | I12: =IF(OR(B12="",J12<>"Có"),0,IFERROR(MAX(0,(F12-G12)/H12),0)) -> 0 | L12: =IF(B12="","","TS-"&TEXT(ROW()-3,"000")) -> TS-009
A13: 46225 | B13: In Bảng QR | C13: Cơ sở vật chất | D13: 1 | E13: 50000 | F13: =IF(OR(B13="",D13="",E13=""),0,D13*E13) -> 50000 | H13: 36 | I13: =IF(OR(B13="",J13<>"Có"),0,IFERROR(MAX(0,(F13-G13)/H13),0)) -> 0 | L13: =IF(B13="","","TS-"&TEXT(ROW()-3,"000")) -> TS-010
A14: 46225 | B14: Khay đá lớn | C14: Cơ sở vật chất | D14: 10 | E14: 25000 | F14: =IF(OR(B14="",D14="",E14=""),0,D14*E14) -> 250000 | H14: 24 | I14: =IF(OR(B14="",J14<>"Có"),0,IFERROR(MAX(0,(F14-G14)/H14),0)) -> 0 | L14: =IF(B14="","","TS-"&TEXT(ROW()-3,"000")) -> TS-011
A15: 46225 | B15: Chân kê bảng quảng cáo | C15: Cơ sở vật chất | D15: 1 | E15: 130000 | F15: =IF(OR(B15="",D15="",E15=""),0,D15*E15) -> 130000 | H15: 12 | I15: =IF(OR(B15="",J15<>"Có"),0,IFERROR(MAX(0,(F15-G15)/H15),0)) -> 0 | L15: =IF(B15="","","TS-"&TEXT(ROW()-3,"000")) -> TS-012
A16: 46225 | B16: In Bảng Quảng Cáo 2 | C16: Cơ sở vật chất | D16: 1 | E16: 130000 | F16: =IF(OR(B16="",D16="",E16=""),0,D16*E16) -> 130000 | I16: =IF(OR(B16="",J16<>"Có"),0,IFERROR(MAX(0,(F16-G16)/H16),0)) -> 0 | L16: =IF(B16="","","TS-"&TEXT(ROW()-3,"000")) -> TS-013
F17: =IF(OR(B17="",D17="",E17=""),0,D17*E17) -> 0 | I17: =IF(OR(B17="",J17<>"Có"),0,IFERROR(MAX(0,(F17-G17)/H17),0)) -> 0 | L17: =IF(B17="","","TS-"&TEXT(ROW()-3,"000"))
F18: =IF(OR(B18="",D18="",E18=""),0,D18*E18) -> 0 | I18: =IF(OR(B18="",J18<>"Có"),0,IFERROR(MAX(0,(F18-G18)/H18),0)) -> 0 | L18: =IF(B18="","","TS-"&TEXT(ROW()-3,"000"))
F19: =IF(OR(B19="",D19="",E19=""),0,D19*E19) -> 0 | I19: =IF(OR(B19="",J19<>"Có"),0,IFERROR(MAX(0,(F19-G19)/H19),0)) -> 0 | L19: =IF(B19="","","TS-"&TEXT(ROW()-3,"000"))
F20: =IF(OR(B20="",D20="",E20=""),0,D20*E20) -> 0 | I20: =IF(OR(B20="",J20<>"Có"),0,IFERROR(MAX(0,(F20-G20)/H20),0)) -> 0 | L20: =IF(B20="","","TS-"&TEXT(ROW()-3,"000"))
F21: =IF(OR(B21="",D21="",E21=""),0,D21*E21) -> 0 | I21: =IF(OR(B21="",J21<>"Có"),0,IFERROR(MAX(0,(F21-G21)/H21),0)) -> 0 | L21: =IF(B21="","","TS-"&TEXT(ROW()-3,"000"))
F22: =IF(OR(B22="",D22="",E22=""),0,D22*E22) -> 0 | I22: =IF(OR(B22="",J22<>"Có"),0,IFERROR(MAX(0,(F22-G22)/H22),0)) -> 0 | L22: =IF(B22="","","TS-"&TEXT(ROW()-3,"000"))
F23: =IF(OR(B23="",D23="",E23=""),0,D23*E23) -> 0 | I23: =IF(OR(B23="",J23<>"Có"),0,IFERROR(MAX(0,(F23-G23)/H23),0)) -> 0 | L23: =IF(B23="","","TS-"&TEXT(ROW()-3,"000"))
F24: =IF(OR(B24="",D24="",E24=""),0,D24*E24) -> 0 | I24: =IF(OR(B24="",J24<>"Có"),0,IFERROR(MAX(0,(F24-G24)/H24),0)) -> 0 | L24: =IF(B24="","","TS-"&TEXT(ROW()-3,"000"))
F25: =IF(OR(B25="",D25="",E25=""),0,D25*E25) -> 0 | I25: =IF(OR(B25="",J25<>"Có"),0,IFERROR(MAX(0,(F25-G25)/H25),0)) -> 0 | L25: =IF(B25="","","TS-"&TEXT(ROW()-3,"000"))
F26: =IF(OR(B26="",D26="",E26=""),0,D26*E26) -> 0 | I26: =IF(OR(B26="",J26<>"Có"),0,IFERROR(MAX(0,(F26-G26)/H26),0)) -> 0 | L26: =IF(B26="","","TS-"&TEXT(ROW()-3,"000"))
F27: =IF(OR(B27="",D27="",E27=""),0,D27*E27) -> 0 | I27: =IF(OR(B27="",J27<>"Có"),0,IFERROR(MAX(0,(F27-G27)/H27),0)) -> 0 | L27: =IF(B27="","","TS-"&TEXT(ROW()-3,"000"))
F28: =IF(OR(B28="",D28="",E28=""),0,D28*E28) -> 0 | I28: =IF(OR(B28="",J28<>"Có"),0,IFERROR(MAX(0,(F28-G28)/H28),0)) -> 0 | L28: =IF(B28="","","TS-"&TEXT(ROW()-3,"000"))
... F203: =IF(OR(B203="",D203="",E203=""),0,D203*E203) -> 0 | I203: =IF(OR(B203="",J203<>"Có"),0,IFERROR(MAX(0,(F203-G203)/H203),0)) -> 0 | L203: =IF(B203="","","TS-"&TEXT(ROW()-3,"000"))
A206: Tổng hợp | B206: Giá trị
A207: Tổng vốn đầu tư | B207: =SUM(F4:F203) -> 2637200
A208: Tổng khấu hao/tháng | B208: =SUMIFS(I4:I203,J4:J203,"Có") -> 91363.889
A209: Khấu hao phân bổ/ly | B209: =IFERROR(B208/'Thiết lập'!$B$9,0) -> 91.363889

Sheet Size
A1: DANH MỤC SIZE — MỖI SIZE MỘT DÒNG
A2: Có sẵn 50 dòng. Nhập size mới vào dòng trống tiếp theo. | I2: Kích hoạt | J2: DS bao bì
A3: Mã size | B3: Tên size | C3: Sữa nền/ly (ml) | D3: Tên bộ ly | E3: Giá bán mặc định (đ) | F3: Kích hoạt | G3: DS tên size | I3: Có | J3: Ly size M
A4: M | B4: Size M | C4: 400 | D4: Bộ ly | E4: 35000 | F4: Có | G4: =IF(AND(B4<>"",F4="Có"),B4,"") -> Size M | I4: Không | J4: Nắp size M
A5: L | B5: Size L | C5: 550 | D5: Bộ ly | E5: 40000 | F5: Có | G5: =IF(AND(B5<>"",F5="Có"),B5,"") -> Size L | J5: Ly size L
A6: =IF(B6="","","SZ-"&TEXT(ROW()-3,"000")) | G6: =IF(AND(B6<>"",F6="Có"),B6,"") | J6: Nắp size L
A7: =IF(B7="","","SZ-"&TEXT(ROW()-3,"000")) | G7: =IF(AND(B7<>"",F7="Có"),B7,"") | J7: Ống hút
A8: =IF(B8="","","SZ-"&TEXT(ROW()-3,"000")) | G8: =IF(AND(B8<>"",F8="Có"),B8,"") | J8: Muỗng
A9: =IF(B9="","","SZ-"&TEXT(ROW()-3,"000")) | G9: =IF(AND(B9<>"",F9="Có"),B9,"") | J9: Túi mang đi
A10: =IF(B10="","","SZ-"&TEXT(ROW()-3,"000")) | G10: =IF(AND(B10<>"",F10="Có"),B10,"") | J10: Bộ ly
A11: =IF(B11="","","SZ-"&TEXT(ROW()-3,"000")) | G11: =IF(AND(B11<>"",F11="Có"),B11,"") | J11: =IF(AND('Hàng hóa'!B20<>"",'Hàng hóa'!C20="Bao bì",'Hàng hóa'!I20="Có"),'Hàng hóa'!B20,"") -> Màng Wrap nhỏ
A12: =IF(B12="","","SZ-"&TEXT(ROW()-3,"000")) | G12: =IF(AND(B12<>"",F12="Có"),B12,"") | J12: =IF(AND('Hàng hóa'!B21<>"",'Hàng hóa'!C21="Bao bì",'Hàng hóa'!I21="Có"),'Hàng hóa'!B21,"")
A13: =IF(B13="","","SZ-"&TEXT(ROW()-3,"000")) | G13: =IF(AND(B13<>"",F13="Có"),B13,"") | J13: =IF(AND('Hàng hóa'!B22<>"",'Hàng hóa'!C22="Bao bì",'Hàng hóa'!I22="Có"),'Hàng hóa'!B22,"")
A14: =IF(B14="","","SZ-"&TEXT(ROW()-3,"000")) | G14: =IF(AND(B14<>"",F14="Có"),B14,"") | J14: =IF(AND('Hàng hóa'!B23<>"",'Hàng hóa'!C23="Bao bì",'Hàng hóa'!I23="Có"),'Hàng hóa'!B23,"")
A15: =IF(B15="","","SZ-"&TEXT(ROW()-3,"000")) | G15: =IF(AND(B15<>"",F15="Có"),B15,"") | J15: =IF(AND('Hàng hóa'!B24<>"",'Hàng hóa'!C24="Bao bì",'Hàng hóa'!I24="Có"),'Hàng hóa'!B24,"")
A16: =IF(B16="","","SZ-"&TEXT(ROW()-3,"000")) | G16: =IF(AND(B16<>"",F16="Có"),B16,"") | J16: =IF(AND('Hàng hóa'!B25<>"",'Hàng hóa'!C25="Bao bì",'Hàng hóa'!I25="Có"),'Hàng hóa'!B25,"")
A17: =IF(B17="","","SZ-"&TEXT(ROW()-3,"000")) | G17: =IF(AND(B17<>"",F17="Có"),B17,"") | J17: =IF(AND('Hàng hóa'!B26<>"",'Hàng hóa'!C26="Bao bì",'Hàng hóa'!I26="Có"),'Hàng hóa'!B26,"")
A18: =IF(B18="","","SZ-"&TEXT(ROW()-3,"000")) | G18: =IF(AND(B18<>"",F18="Có"),B18,"") | J18: =IF(AND('Hàng hóa'!B27<>"",'Hàng hóa'!C27="Bao bì",'Hàng hóa'!I27="Có"),'Hàng hóa'!B27,"")
A19: =IF(B19="","","SZ-"&TEXT(ROW()-3,"000")) | G19: =IF(AND(B19<>"",F19="Có"),B19,"") | J19: =IF(AND('Hàng hóa'!B28<>"",'Hàng hóa'!C28="Bao bì",'Hàng hóa'!I28="Có"),'Hàng hóa'!B28,"")
A20: =IF(B20="","","SZ-"&TEXT(ROW()-3,"000")) | G20: =IF(AND(B20<>"",F20="Có"),B20,"") | J20: =IF(AND('Hàng hóa'!B29<>"",'Hàng hóa'!C29="Bao bì",'Hàng hóa'!I29="Có"),'Hàng hóa'!B29,"")
A21: =IF(B21="","","SZ-"&TEXT(ROW()-3,"000")) | G21: =IF(AND(B21<>"",F21="Có"),B21,"") | J21: =IF(AND('Hàng hóa'!B30<>"",'Hàng hóa'!C30="Bao bì",'Hàng hóa'!I30="Có"),'Hàng hóa'!B30,"")
A22: =IF(B22="","","SZ-"&TEXT(ROW()-3,"000")) | G22: =IF(AND(B22<>"",F22="Có"),B22,"") | J22: =IF(AND('Hàng hóa'!B31<>"",'Hàng hóa'!C31="Bao bì",'Hàng hóa'!I31="Có"),'Hàng hóa'!B31,"")
... A53: =IF(B53="","","SZ-"&TEXT(ROW()-3,"000")) | G53: =IF(AND(B53<>"",F53="Có"),B53,"") | J53: =IF(AND('Hàng hóa'!B62<>"",'Hàng hóa'!C62="Bao bì",'Hàng hóa'!I62="Có"),'Hàng hóa'!B62,"")
J54: =IF(AND('Hàng hóa'!B63<>"",'Hàng hóa'!C63="Bao bì",'Hàng hóa'!I63="Có"),'Hàng hóa'!B63,"")
J55: =IF(AND('Hàng hóa'!B64<>"",'Hàng hóa'!C64="Bao bì",'Hàng hóa'!I64="Có"),'Hàng hóa'!B64,"")
J56: =IF(AND('Hàng hóa'!B65<>"",'Hàng hóa'!C65="Bao bì",'Hàng hóa'!I65="Có"),'Hàng hóa'!B65,"")
J57: =IF(AND('Hàng hóa'!B66<>"",'Hàng hóa'!C66="Bao bì",'Hàng hóa'!I66="Có"),'Hàng hóa'!B66,"")
J58: =IF(AND('Hàng hóa'!B67<>"",'Hàng hóa'!C67="Bao bì",'Hàng hóa'!I67="Có"),'Hàng hóa'!B67,"")
J59: =IF(AND('Hàng hóa'!B68<>"",'Hàng hóa'!C68="Bao bì",'Hàng hóa'!I68="Có"),'Hàng hóa'!B68,"")
J60: =IF(AND('Hàng hóa'!B69<>"",'Hàng hóa'!C69="Bao bì",'Hàng hóa'!I69="Có"),'Hàng hóa'!B69,"")
J61: =IF(AND('Hàng hóa'!B70<>"",'Hàng hóa'!C70="Bao bì",'Hàng hóa'!I70="Có"),'Hàng hóa'!B70,"")
J62: =IF(AND('Hàng hóa'!B71<>"",'Hàng hóa'!C71="Bao bì",'Hàng hóa'!I71="Có"),'Hàng hóa'!B71,"")
J63: =IF(AND('Hàng hóa'!B72<>"",'Hàng hóa'!C72="Bao bì",'Hàng hóa'!I72="Có"),'Hàng hóa'!B72,"")
J64: =IF(AND('Hàng hóa'!B73<>"",'Hàng hóa'!C73="Bao bì",'Hàng hóa'!I73="Có"),'Hàng hóa'!B73,"")
J65: =IF(AND('Hàng hóa'!B74<>"",'Hàng hóa'!C74="Bao bì",'Hàng hóa'!I74="Có"),'Hàng hóa'!B74,"")
... J194: =IF(AND('Hàng hóa'!B203<>"",'Hàng hóa'!C203="Bao bì",'Hàng hóa'!I203="Có"),'Hàng hóa'!B203,"")
J195: =IF(AND('Hàng hóa'!B196<>"",'Hàng hóa'!C196="Bao bì",'Hàng hóa'!I196="Có"),'Hàng hóa'!B196,"")
J196: =IF(AND('Hàng hóa'!B197<>"",'Hàng hóa'!C197="Bao bì",'Hàng hóa'!I197="Có"),'Hàng hóa'!B197,"")
J197: =IF(AND('Hàng hóa'!B198<>"",'Hàng hóa'!C198="Bao bì",'Hàng hóa'!I198="Có"),'Hàng hóa'!B198,"")
J198: =IF(AND('Hàng hóa'!B199<>"",'Hàng hóa'!C199="Bao bì",'Hàng hóa'!I199="Có"),'Hàng hóa'!B199,"")
...

Sheet Sản phẩm
A1: DANH MỤC SẢN PHẨM — THÊM MÓN MỚI Ở DÒNG TRỐNG TIẾP THEO
A2: Chỉ cần chọn Tên topping và Tên size. Tên sản phẩm, giá bán và các loại cost sẽ tự liên kết. | R2: DS topping | S2: DS size | T2: Kích hoạt
A3: Mã SP | B3: Tên topping | C3: Tên size | D3: Tên sản phẩm | E3: Topping (g) | F3: Giá bán (đ) | G3: Sữa nền (ml) | H3: Cost sữa xem trước | I3: Cost topping | J3: Cost bao bì | K3: Overhead | L3: Cost biến đổi | M3: Phân bổ cố định | N3: Full cost | O3: Kích hoạt | P3: DS tên sản phẩm | R3: Oreo | S3: =IF(Size!G4<>"",Size!G4,"") -> Size M | T3: Có
A4: M-OREO | B4: Oreo | C4: Size M | D4: =IF(OR(B4="",C4=""),"",B4&" - "&C4) -> Oreo - Size M | E4: 15 | F4: {=IFERROR(INDEX(Size!$E$4:$E$53,MATCH(C4,Size!$B$4:$B$53,0)),0)} -> 35000 | G4: {=IFERROR(INDEX(Size!$C$4:$C$53,MATCH(C4,Size!$B$4:$B$53,0)),0)} -> 400 | H4: =IF(A4="","",G4*'Mẻ sữa'!$U$5) -> 11862.083 | I4: {=IFERROR(E4*INDEX('Hàng hóa'!$H$4:$H$203,MATCH(B4,'Hàng hóa'!$B$4:$B$203,0)),0)} -> 3562.5 | J4: {=IF(A4="","",IFERROR(INDEX('Hàng hóa'!$H$4:$H$203,MATCH(INDEX(Size!$D$4:$D$53,MATCH(C4,Size!$B$4:$B$53,0)),'Hàng hóa'!$B$4:$B$203,0)),0)+IFERROR(INDEX('Hàng hóa'!$H$4:$H$203,MATCH("Ống hút",'Hàng hóa'!$B$4:$B$203,0)),0)+IFERROR(INDEX('Hàng hóa'!$H$4:$H$203,MATCH("Muỗng",'Hàng hóa'!$B$4:$B$203,0)),0)+IFERROR(INDEX('Hàng hóa'!$H$4:$H$203,MATCH("Túi mang đi",'Hàng hóa'!$B$4:$B$203,0)),0))} -> 900 | K4: =IF(A4="","",(H4+I4+J4)*'Thiết lập'!$B$8) -> 816.22917 | L4: =IF(A4="","",SUM(H4:K4)) -> 17140.812 | M4: =IF(A4="","",'Thiết lập'!$B$12) -> 91.363889 | N4: =IF(A4="","",L4+M4) -> 17232.176 | O4: Có | P4: =IF(AND(D4<>"",O4="Có"),D4,"") -> Oreo - Size M | R4: Dừa non | S4: =IF(Size!G5<>"",Size!G5,"") -> Size L | T4: Không
A5: L-OREO | B5: Oreo | C5: Size L | D5: =IF(OR(B5="",C5=""),"",B5&" - "&C5) -> Oreo - Size L | E5: 15 | F5: {=IFERROR(INDEX(Size!$E$4:$E$53,MATCH(C5,Size!$B$4:$B$53,0)),0)} -> 40000 | G5: {=IFERROR(INDEX(Size!$C$4:$C$53,MATCH(C5,Size!$B$4:$B$53,0)),0)} -> 550 | H5: =IF(A5="","",G5*'Mẻ sữa'!$U$5) -> 16310.365 | I5: {=IFERROR(E5*INDEX('Hàng hóa'!$H$4:$H$203,MATCH(B5,'Hàng hóa'!$B$4:$B$203,0)),0)} -> 3562.5 | J5: {=IF(A5="","",IFERROR(INDEX('Hàng hóa'!$H$4:$H$203,MATCH(INDEX(Size!$D$4:$D$53,MATCH(C5,Size!$B$4:$B$53,0)),'Hàng hóa'!$B$4:$B$203,0)),0)+IFERROR(INDEX('Hàng hóa'!$H$4:$H$203,MATCH("Ống hút",'Hàng hóa'!$B$4:$B$203,0)),0)+IFERROR(INDEX('Hàng hóa'!$H$4:$H$203,MATCH("Muỗng",'Hàng hóa'!$B$4:$B$203,0)),0)+IFERROR(INDEX('Hàng hóa'!$H$4:$H$203,MATCH("Túi mang đi",'Hàng hóa'!$B$4:$B$203,0)),0))} -> 900 | K5: =IF(A5="","",(H5+I5+J5)*'Thiết lập'!$B$8) -> 1038.6432 | L5: =IF(A5="","",SUM(H5:K5)) -> 21811.508 | M5: =IF(A5="","",'Thiết lập'!$B$12) -> 91.363889 | N5: =IF(A5="","",L5+M5) -> 21902.872 | O5: Có | P5: =IF(AND(D5<>"",O5="Có"),D5,"") -> Oreo - Size L | R5: Dâu giòn | S5: =IF(Size!G6<>"",Size!G6,"")
A6: M-DUA | B6: Dừa non | C6: Size M | D6: =IF(OR(B6="",C6=""),"",B6&" - "&C6) -> Dừa non - Size M | E6: 15 | F6: {=IFERROR(INDEX(Size!$E$4:$E$53,MATCH(C6,Size!$B$4:$B$53,0)),0)} -> 35000 | G6: {=IFERROR(INDEX(Size!$C$4:$C$53,MATCH(C6,Size!$B$4:$B$53,0)),0)} -> 400 | H6: =IF(A6="","",G6*'Mẻ sữa'!$U$5) -> 11862.083 | I6: {=IFERROR(E6*INDEX('Hàng hóa'!$H$4:$H$203,MATCH(B6,'Hàng hóa'!$B$4:$B$203,0)),0)} -> 1581.8182 | J6: {=IF(A6="","",IFERROR(INDEX('Hàng hóa'!$H$4:$H$203,MATCH(INDEX(Size!$D$4:$D$53,MATCH(C6,Size!$B$4:$B$53,0)),'Hàng hóa'!$B$4:$B$203,0)),0)+IFERROR(INDEX('Hàng hóa'!$H$4:$H$203,MATCH("Ống hút",'Hàng hóa'!$B$4:$B$203,0)),0)+IFERROR(INDEX('Hàng hóa'!$H$4:$H$203,MATCH("Muỗng",'Hàng hóa'!$B$4:$B$203,0)),0)+IFERROR(INDEX('Hàng hóa'!$H$4:$H$203,MATCH("Túi mang đi",'Hàng hóa'!$B$4:$B$203,0)),0))} -> 900 | K6: =IF(A6="","",(H6+I6+J6)*'Thiết lập'!$B$8) -> 717.19508 | L6: =IF(A6="","",SUM(H6:K6)) -> 15061.097 | M6: =IF(A6="","",'Thiết lập'!$B$12) -> 91.363889 | N6: =IF(A6="","",L6+M6) -> 15152.46 | O6: Có | P6: =IF(AND(D6<>"",O6="Có"),D6,"") -> Dừa non - Size M | R6: Sữa chua sấy | S6: =IF(Size!G7<>"",Size!G7,"")
A7: L-DUA | B7: Dừa non | C7: Size L | D7: =IF(OR(B7="",C7=""),"",B7&" - "&C7) -> Dừa non - Size L | E7: 15 | F7: {=IFERROR(INDEX(Size!$E$4:$E$53,MATCH(C7,Size!$B$4:$B$53,0)),0)} -> 40000 | G7: {=IFERROR(INDEX(Size!$C$4:$C$53,MATCH(C7,Size!$B$4:$B$53,0)),0)} -> 550 | H7: =IF(A7="","",G7*'Mẻ sữa'!$U$5) -> 16310.365 | I7: {=IFERROR(E7*INDEX('Hàng hóa'!$H$4:$H$203,MATCH(B7,'Hàng hóa'!$B$4:$B$203,0)),0)} -> 1581.8182 | J7: {=IF(A7="","",IFERROR(INDEX('Hàng hóa'!$H$4:$H$203,MATCH(INDEX(Size!$D$4:$D$53,MATCH(C7,Size!$B$4:$B$53,0)),'Hàng hóa'!$B$4:$B$203,0)),0)+IFERROR(INDEX('Hàng hóa'!$H$4:$H$203,MATCH("Ống hút",'Hàng hóa'!$B$4:$B$203,0)),0)+IFERROR(INDEX('Hàng hóa'!$H$4:$H$203,MATCH("Muỗng",'Hàng hóa'!$B$4:$B$203,0)),0)+IFERROR(INDEX('Hàng hóa'!$H$4:$H$203,MATCH("Túi mang đi",'Hàng hóa'!$B$4:$B$203,0)),0))} -> 900 | K7: =IF(A7="","",(H7+I7+J7)*'Thiết lập'!$B$8) -> 939.60914 | L7: =IF(A7="","",SUM(H7:K7)) -> 19731.792 | M7: =IF(A7="","",'Thiết lập'!$B$12) -> 91.363889 | N7: =IF(A7="","",L7+M7) -> 19823.156 | O7: Có | P7: =IF(AND(D7<>"",O7="Có"),D7,"") -> Dừa non - Size L | R7: Choco Ball | S7: =IF(Size!G8<>"",Size!G8,"")
A8: M-DAU | B8: Dâu giòn | C8: Size M | D8: =IF(OR(B8="",C8=""),"",B8&" - "&C8) -> Dâu giòn - Size M | E8: 15 | F8: {=IFERROR(INDEX(Size!$E$4:$E$53,MATCH(C8,Size!$B$4:$B$53,0)),0)} -> 35000 | G8: {=IFERROR(INDEX(Size!$C$4:$C$53,MATCH(C8,Size!$B$4:$B$53,0)),0)} -> 400 | H8: =IF(A8="","",G8*'Mẻ sữa'!$U$5) -> 11862.083 | I8: {=IFERROR(E8*INDEX('Hàng hóa'!$H$4:$H$203,MATCH(B8,'Hàng hóa'!$B$4:$B$203,0)),0)} -> 5940000 | J8: {=IF(A8="","",IFERROR(INDEX('Hàng hóa'!$H$4:$H$203,MATCH(INDEX(Size!$D$4:$D$53,MATCH(C8,Size!$B$4:$B$53,0)),'Hàng hóa'!$B$4:$B$203,0)),0)+IFERROR(INDEX('Hàng hóa'!$H$4:$H$203,MATCH("Ống hút",'Hàng hóa'!$B$4:$B$203,0)),0)+IFERROR(INDEX('Hàng hóa'!$H$4:$H$203,MATCH("Muỗng",'Hàng hóa'!$B$4:$B$203,0)),0)+IFERROR(INDEX('Hàng hóa'!$H$4:$H$203,MATCH("Túi mang đi",'Hàng hóa'!$B$4:$B$203,0)),0))} -> 900 | K8: =IF(A8="","",(H8+I8+J8)*'Thiết lập'!$B$8) -> 297638.1 | L8: =IF(A8="","",SUM(H8:K8)) -> 6250400.2 | M8: =IF(A8="","",'Thiết lập'!$B$12) -> 91.363889 | N8: =IF(A8="","",L8+M8) -> 6250491.6 | O8: Có | P8: =IF(AND(D8<>"",O8="Có"),D8,"") -> Dâu giòn - Size M | R8: =IF(AND('Hàng hóa'!B20<>"",'Hàng hóa'!C20="Topping",'Hàng hóa'!I20="Có"),'Hàng hóa'!B20,"") | S8: =IF(Size!G9<>"",Size!G9,"")
A9: L-DAU | B9: Dâu giòn | C9: Size L | D9: =IF(OR(B9="",C9=""),"",B9&" - "&C9) -> Dâu giòn - Size L | E9: 15 | F9: {=IFERROR(INDEX(Size!$E$4:$E$53,MATCH(C9,Size!$B$4:$B$53,0)),0)} -> 40000 | G9: {=IFERROR(INDEX(Size!$C$4:$C$53,MATCH(C9,Size!$B$4:$B$53,0)),0)} -> 550 | H9: =IF(A9="","",G9*'Mẻ sữa'!$U$5) -> 16310.365 | I9: {=IFERROR(E9*INDEX('Hàng hóa'!$H$4:$H$203,MATCH(B9,'Hàng hóa'!$B$4:$B$203,0)),0)} -> 5940000 | J9: {=IF(A9="","",IFERROR(INDEX('Hàng hóa'!$H$4:$H$203,MATCH(INDEX(Size!$D$4:$D$53,MATCH(C9,Size!$B$4:$B$53,0)),'Hàng hóa'!$B$4:$B$203,0)),0)+IFERROR(INDEX('Hàng hóa'!$H$4:$H$203,MATCH("Ống hút",'Hàng hóa'!$B$4:$B$203,0)),0)+IFERROR(INDEX('Hàng hóa'!$H$4:$H$203,MATCH("Muỗng",'Hàng hóa'!$B$4:$B$203,0)),0)+IFERROR(INDEX('Hàng hóa'!$H$4:$H$203,MATCH("Túi mang đi",'Hàng hóa'!$B$4:$B$203,0)),0))} -> 900 | K9: =IF(A9="","",(H9+I9+J9)*'Thiết lập'!$B$8) -> 297860.52 | L9: =IF(A9="","",SUM(H9:K9)) -> 6255070.9 | M9: =IF(A9="","",'Thiết lập'!$B$12) -> 91.363889 | N9: =IF(A9="","",L9+M9) -> 6255162.2 | O9: Có | P9: =IF(AND(D9<>"",O9="Có"),D9,"") -> Dâu giòn - Size L | R9: =IF(AND('Hàng hóa'!B21<>"",'Hàng hóa'!C21="Topping",'Hàng hóa'!I21="Có"),'Hàng hóa'!B21,"") | S9: =IF(Size!G10<>"",Size!G10,"")
A10: M-SC | B10: Sữa chua sấy | C10: Size M | D10: =IF(OR(B10="",C10=""),"",B10&" - "&C10) -> Sữa chua sấy - Size M | E10: 15 | F10: {=IFERROR(INDEX(Size!$E$4:$E$53,MATCH(C10,Size!$B$4:$B$53,0)),0)} -> 35000 | G10: {=IFERROR(INDEX(Size!$C$4:$C$53,MATCH(C10,Size!$B$4:$B$53,0)),0)} -> 400 | H10: =IF(A10="","",G10*'Mẻ sữa'!$U$5) -> 11862.083 | I10: {=IFERROR(E10*INDEX('Hàng hóa'!$H$4:$H$203,MATCH(B10,'Hàng hóa'!$B$4:$B$203,0)),0)} -> 4855500 | J10: {=IF(A10="","",IFERROR(INDEX('Hàng hóa'!$H$4:$H$203,MATCH(INDEX(Size!$D$4:$D$53,MATCH(C10,Size!$B$4:$B$53,0)),'Hàng hóa'!$B$4:$B$203,0)),0)+IFERROR(INDEX('Hàng hóa'!$H$4:$H$203,MATCH("Ống hút",'Hàng hóa'!$B$4:$B$203,0)),0)+IFERROR(INDEX('Hàng hóa'!$H$4:$H$203,MATCH("Muỗng",'Hàng hóa'!$B$4:$B$203,0)),0)+IFERROR(INDEX('Hàng hóa'!$H$4:$H$203,MATCH("Túi mang đi",'Hàng hóa'!$B$4:$B$203,0)),0))} -> 900 | K10: =IF(A10="","",(H10+I10+J10)*'Thiết lập'!$B$8) -> 243413.1 | L10: =IF(A10="","",SUM(H10:K10)) -> 5111675.2 | M10: =IF(A10="","",'Thiết lập'!$B$12) -> 91.363889 | N10: =IF(A10="","",L10+M10) -> 5111766.6 | O10: Có | P10: =IF(AND(D10<>"",O10="Có"),D10,"") -> Sữa chua sấy - Size M | R10: =IF(AND('Hàng hóa'!B22<>"",'Hàng hóa'!C22="Topping",'Hàng hóa'!I22="Có"),'Hàng hóa'!B22,"") | S10: =IF(Size!G11<>"",Size!G11,"")
A11: L-SC | B11: Sữa chua sấy | C11: Size L | D11: =IF(OR(B11="",C11=""),"",B11&" - "&C11) -> Sữa chua sấy - Size L | E11: 15 | F11: {=IFERROR(INDEX(Size!$E$4:$E$53,MATCH(C11,Size!$B$4:$B$53,0)),0)} -> 40000 | G11: {=IFERROR(INDEX(Size!$C$4:$C$53,MATCH(C11,Size!$B$4:$B$53,0)),0)} -> 550 | H11: =IF(A11="","",G11*'Mẻ sữa'!$U$5) -> 16310.365 | I11: {=IFERROR(E11*INDEX('Hàng hóa'!$H$4:$H$203,MATCH(B11,'Hàng hóa'!$B$4:$B$203,0)),0)} -> 4855500 | J11: {=IF(A11="","",IFERROR(INDEX('Hàng hóa'!$H$4:$H$203,MATCH(INDEX(Size!$D$4:$D$53,MATCH(C11,Size!$B$4:$B$53,0)),'Hàng hóa'!$B$4:$B$203,0)),0)+IFERROR(INDEX('Hàng hóa'!$H$4:$H$203,MATCH("Ống hút",'Hàng hóa'!$B$4:$B$203,0)),0)+IFERROR(INDEX('Hàng hóa'!$H$4:$H$203,MATCH("Muỗng",'Hàng hóa'!$B$4:$B$203,0)),0)+IFERROR(INDEX('Hàng hóa'!$H$4:$H$203,MATCH("Túi mang đi",'Hàng hóa'!$B$4:$B$203,0)),0))} -> 900 | K11: =IF(A11="","",(H11+I11+J11)*'Thiết lập'!$B$8) -> 243635.52 | L11: =IF(A11="","",SUM(H11:K11)) -> 5116345.9 | M11: =IF(A11="","",'Thiết lập'!$B$12) -> 91.363889 | N11: =IF(A11="","",L11+M11) -> 5116437.2 | O11: Có | P11: =IF(AND(D11<>"",O11="Có"),D11,"") -> Sữa chua sấy - Size L | R11: =IF(AND('Hàng hóa'!B23<>"",'Hàng hóa'!C23="Topping",'Hàng hóa'!I23="Có"),'Hàng hóa'!B23,"") | S11: =IF(Size!G12<>"",Size!G12,"")
A12: M-CHOCO | B12: Choco Ball | C12: Size M | D12: =IF(OR(B12="",C12=""),"",B12&" - "&C12) -> Choco Ball - Size M | E12: 15 | F12: {=IFERROR(INDEX(Size!$E$4:$E$53,MATCH(C12,Size!$B$4:$B$53,0)),0)} -> 35000 | G12: {=IFERROR(INDEX(Size!$C$4:$C$53,MATCH(C12,Size!$B$4:$B$53,0)),0)} -> 400 | H12: =IF(A12="","",G12*'Mẻ sữa'!$U$5) -> 11862.083 | I12: {=IFERROR(E12*INDEX('Hàng hóa'!$H$4:$H$203,MATCH(B12,'Hàng hóa'!$B$4:$B$203,0)),0)} -> 4280000 | J12: {=IF(A12="","",IFERROR(INDEX('Hàng hóa'!$H$4:$H$203,MATCH(INDEX(Size!$D$4:$D$53,MATCH(C12,Size!$B$4:$B$53,0)),'Hàng hóa'!$B$4:$B$203,0)),0)+IFERROR(INDEX('Hàng hóa'!$H$4:$H$203,MATCH("Ống hút",'Hàng hóa'!$B$4:$B$203,0)),0)+IFERROR(INDEX('Hàng hóa'!$H$4:$H$203,MATCH("Muỗng",'Hàng hóa'!$B$4:$B$203,0)),0)+IFERROR(INDEX('Hàng hóa'!$H$4:$H$203,MATCH("Túi mang đi",'Hàng hóa'!$B$4:$B$203,0)),0))} -> 900 | K12: =IF(A12="","",(H12+I12+J12)*'Thiết lập'!$B$8) -> 214638.1 | L12: =IF(A12="","",SUM(H12:K12)) -> 4507400.2 | M12: =IF(A12="","",'Thiết lập'!$B$12) -> 91.363889 | N12: =IF(A12="","",L12+M12) -> 4507491.6 | O12: Có | P12: =IF(AND(D12<>"",O12="Có"),D12,"") -> Choco Ball - Size M | R12: =IF(AND('Hàng hóa'!B24<>"",'Hàng hóa'!C24="Topping",'Hàng hóa'!I24="Có"),'Hàng hóa'!B24,"") | S12: =IF(Size!G13<>"",Size!G13,"")
A13: L-CHOCO | B13: Choco Ball | C13: Size L | D13: =IF(OR(B13="",C13=""),"",B13&" - "&C13) -> Choco Ball - Size L | E13: 15 | F13: {=IFERROR(INDEX(Size!$E$4:$E$53,MATCH(C13,Size!$B$4:$B$53,0)),0)} -> 40000 | G13: {=IFERROR(INDEX(Size!$C$4:$C$53,MATCH(C13,Size!$B$4:$B$53,0)),0)} -> 550 | H13: =IF(A13="","",G13*'Mẻ sữa'!$U$5) -> 16310.365 | I13: {=IFERROR(E13*INDEX('Hàng hóa'!$H$4:$H$203,MATCH(B13,'Hàng hóa'!$B$4:$B$203,0)),0)} -> 4280000 | J13: {=IF(A13="","",IFERROR(INDEX('Hàng hóa'!$H$4:$H$203,MATCH(INDEX(Size!$D$4:$D$53,MATCH(C13,Size!$B$4:$B$53,0)),'Hàng hóa'!$B$4:$B$203,0)),0)+IFERROR(INDEX('Hàng hóa'!$H$4:$H$203,MATCH("Ống hút",'Hàng hóa'!$B$4:$B$203,0)),0)+IFERROR(INDEX('Hàng hóa'!$H$4:$H$203,MATCH("Muỗng",'Hàng hóa'!$B$4:$B$203,0)),0)+IFERROR(INDEX('Hàng hóa'!$H$4:$H$203,MATCH("Túi mang đi",'Hàng hóa'!$B$4:$B$203,0)),0))} -> 900 | K13: =IF(A13="","",(H13+I13+J13)*'Thiết lập'!$B$8) -> 214860.52 | L13: =IF(A13="","",SUM(H13:K13)) -> 4512070.9 | M13: =IF(A13="","",'Thiết lập'!$B$12) -> 91.363889 | N13: =IF(A13="","",L13+M13) -> 4512162.2 | O13: Có | P13: =IF(AND(D13<>"",O13="Có"),D13,"") -> Choco Ball - Size L | R13: =IF(AND('Hàng hóa'!B25<>"",'Hàng hóa'!C25="Topping",'Hàng hóa'!I25="Có"),'Hàng hóa'!B25,"") | S13: =IF(Size!G14<>"",Size!G14,"")
A14: =IF(OR(B14="",C14=""),"","SP-"&TEXT(ROW()-3,"000")) | D14: =IF(OR(B14="",C14=""),"",B14&" - "&C14) | F14: {=IFERROR(INDEX(Size!$E$4:$E$53,MATCH(C14,Size!$B$4:$B$53,0)),0)} -> 0 | G14: {=IFERROR(INDEX(Size!$C$4:$C$53,MATCH(C14,Size!$B$4:$B$53,0)),0)} -> 0 | H14: =IF(A14="","",G14*'Mẻ sữa'!$U$5) | I14: {=IFERROR(E14*INDEX('Hàng hóa'!$H$4:$H$203,MATCH(B14,'Hàng hóa'!$B$4:$B$203,0)),0)} -> 0 | J14: {=IF(A14="","",IFERROR(INDEX('Hàng hóa'!$H$4:$H$203,MATCH(INDEX(Size!$D$4:$D$53,MATCH(C14,Size!$B$4:$B$53,0)),'Hàng hóa'!$B$4:$B$203,0)),0)+IFERROR(INDEX('Hàng hóa'!$H$4:$H$203,MATCH("Ống hút",'Hàng hóa'!$B$4:$B$203,0)),0)+IFERROR(INDEX('Hàng hóa'!$H$4:$H$203,MATCH("Muỗng",'Hàng hóa'!$B$4:$B$203,0)),0)+IFERROR(INDEX('Hàng hóa'!$H$4:$H$203,MATCH("Túi mang đi",'Hàng hóa'!$B$4:$B$203,0)),0))} | K14: =IF(A14="","",(H14+I14+J14)*'Thiết lập'!$B$8) | L14: =IF(A14="","",SUM(H14:K14)) | M14: =IF(A14="","",'Thiết lập'!$B$12) | N14: =IF(A14="","",L14+M14) | P14: =IF(AND(D14<>"",O14="Có"),D14,"") | R14: =IF(AND('Hàng hóa'!B26<>"",'Hàng hóa'!C26="Topping",'Hàng hóa'!I26="Có"),'Hàng hóa'!B26,"") | S14: =IF(Size!G15<>"",Size!G15,"")
A15: =IF(OR(B15="",C15=""),"","SP-"&TEXT(ROW()-3,"000")) | D15: =IF(OR(B15="",C15=""),"",B15&" - "&C15) | F15: {=IFERROR(INDEX(Size!$E$4:$E$53,MATCH(C15,Size!$B$4:$B$53,0)),0)} -> 0 | G15: {=IFERROR(INDEX(Size!$C$4:$C$53,MATCH(C15,Size!$B$4:$B$53,0)),0)} -> 0 | H15: =IF(A15="","",G15*'Mẻ sữa'!$U$5) | I15: {=IFERROR(E15*INDEX('Hàng hóa'!$H$4:$H$203,MATCH(B15,'Hàng hóa'!$B$4:$B$203,0)),0)} -> 0 | J15: {=IF(A15="","",IFERROR(INDEX('Hàng hóa'!$H$4:$H$203,MATCH(INDEX(Size!$D$4:$D$53,MATCH(C15,Size!$B$4:$B$53,0)),'Hàng hóa'!$B$4:$B$203,0)),0)+IFERROR(INDEX('Hàng hóa'!$H$4:$H$203,MATCH("Ống hút",'Hàng hóa'!$B$4:$B$203,0)),0)+IFERROR(INDEX('Hàng hóa'!$H$4:$H$203,MATCH("Muỗng",'Hàng hóa'!$B$4:$B$203,0)),0)+IFERROR(INDEX('Hàng hóa'!$H$4:$H$203,MATCH("Túi mang đi",'Hàng hóa'!$B$4:$B$203,0)),0))} | K15: =IF(A15="","",(H15+I15+J15)*'Thiết lập'!$B$8) | L15: =IF(A15="","",SUM(H15:K15)) | M15: =IF(A15="","",'Thiết lập'!$B$12) | N15: =IF(A15="","",L15+M15) | P15: =IF(AND(D15<>"",O15="Có"),D15,"") | R15: =IF(AND('Hàng hóa'!B27<>"",'Hàng hóa'!C27="Topping",'Hàng hóa'!I27="Có"),'Hàng hóa'!B27,"") | S15: =IF(Size!G16<>"",Size!G16,"")
A16: =IF(OR(B16="",C16=""),"","SP-"&TEXT(ROW()-3,"000")) | D16: =IF(OR(B16="",C16=""),"",B16&" - "&C16) | F16: {=IFERROR(INDEX(Size!$E$4:$E$53,MATCH(C16,Size!$B$4:$B$53,0)),0)} -> 0 | G16: {=IFERROR(INDEX(Size!$C$4:$C$53,MATCH(C16,Size!$B$4:$B$53,0)),0)} -> 0 | H16: =IF(A16="","",G16*'Mẻ sữa'!$U$5) | I16: {=IFERROR(E16*INDEX('Hàng hóa'!$H$4:$H$203,MATCH(B16,'Hàng hóa'!$B$4:$B$203,0)),0)} -> 0 | J16: {=IF(A16="","",IFERROR(INDEX('Hàng hóa'!$H$4:$H$203,MATCH(INDEX(Size!$D$4:$D$53,MATCH(C16,Size!$B$4:$B$53,0)),'Hàng hóa'!$B$4:$B$203,0)),0)+IFERROR(INDEX('Hàng hóa'!$H$4:$H$203,MATCH("Ống hút",'Hàng hóa'!$B$4:$B$203,0)),0)+IFERROR(INDEX('Hàng hóa'!$H$4:$H$203,MATCH("Muỗng",'Hàng hóa'!$B$4:$B$203,0)),0)+IFERROR(INDEX('Hàng hóa'!$H$4:$H$203,MATCH("Túi mang đi",'Hàng hóa'!$B$4:$B$203,0)),0))} | K16: =IF(A16="","",(H16+I16+J16)*'Thiết lập'!$B$8) | L16: =IF(A16="","",SUM(H16:K16)) | M16: =IF(A16="","",'Thiết lập'!$B$12) | N16: =IF(A16="","",L16+M16) | P16: =IF(AND(D16<>"",O16="Có"),D16,"") | R16: =IF(AND('Hàng hóa'!B28<>"",'Hàng hóa'!C28="Topping",'Hàng hóa'!I28="Có"),'Hàng hóa'!B28,"") | S16: =IF(Size!G17<>"",Size!G17,"")
A17: =IF(OR(B17="",C17=""),"","SP-"&TEXT(ROW()-3,"000")) | D17: =IF(OR(B17="",C17=""),"",B17&" - "&C17) | F17: {=IFERROR(INDEX(Size!$E$4:$E$53,MATCH(C17,Size!$B$4:$B$53,0)),0)} -> 0 | G17: {=IFERROR(INDEX(Size!$C$4:$C$53,MATCH(C17,Size!$B$4:$B$53,0)),0)} -> 0 | H17: =IF(A17="","",G17*'Mẻ sữa'!$U$5) | I17: {=IFERROR(E17*INDEX('Hàng hóa'!$H$4:$H$203,MATCH(B17,'Hàng hóa'!$B$4:$B$203,0)),0)} -> 0 | J17: {=IF(A17="","",IFERROR(INDEX('Hàng hóa'!$H$4:$H$203,MATCH(INDEX(Size!$D$4:$D$53,MATCH(C17,Size!$B$4:$B$53,0)),'Hàng hóa'!$B$4:$B$203,0)),0)+IFERROR(INDEX('Hàng hóa'!$H$4:$H$203,MATCH("Ống hút",'Hàng hóa'!$B$4:$B$203,0)),0)+IFERROR(INDEX('Hàng hóa'!$H$4:$H$203,MATCH("Muỗng",'Hàng hóa'!$B$4:$B$203,0)),0)+IFERROR(INDEX('Hàng hóa'!$H$4:$H$203,MATCH("Túi mang đi",'Hàng hóa'!$B$4:$B$203,0)),0))} | K17: =IF(A17="","",(H17+I17+J17)*'Thiết lập'!$B$8) | L17: =IF(A17="","",SUM(H17:K17)) | M17: =IF(A17="","",'Thiết lập'!$B$12) | N17: =IF(A17="","",L17+M17) | P17: =IF(AND(D17<>"",O17="Có"),D17,"") | R17: =IF(AND('Hàng hóa'!B29<>"",'Hàng hóa'!C29="Topping",'Hàng hóa'!I29="Có"),'Hàng hóa'!B29,"") | S17: =IF(Size!G18<>"",Size!G18,"")
A18: =IF(OR(B18="",C18=""),"","SP-"&TEXT(ROW()-3,"000")) | D18: =IF(OR(B18="",C18=""),"",B18&" - "&C18) | F18: {=IFERROR(INDEX(Size!$E$4:$E$53,MATCH(C18,Size!$B$4:$B$53,0)),0)} -> 0 | G18: {=IFERROR(INDEX(Size!$C$4:$C$53,MATCH(C18,Size!$B$4:$B$53,0)),0)} -> 0 | H18: =IF(A18="","",G18*'Mẻ sữa'!$U$5) | I18: {=IFERROR(E18*INDEX('Hàng hóa'!$H$4:$H$203,MATCH(B18,'Hàng hóa'!$B$4:$B$203,0)),0)} -> 0 | J18: {=IF(A18="","",IFERROR(INDEX('Hàng hóa'!$H$4:$H$203,MATCH(INDEX(Size!$D$4:$D$53,MATCH(C18,Size!$B$4:$B$53,0)),'Hàng hóa'!$B$4:$B$203,0)),0)+IFERROR(INDEX('Hàng hóa'!$H$4:$H$203,MATCH("Ống hút",'Hàng hóa'!$B$4:$B$203,0)),0)+IFERROR(INDEX('Hàng hóa'!$H$4:$H$203,MATCH("Muỗng",'Hàng hóa'!$B$4:$B$203,0)),0)+IFERROR(INDEX('Hàng hóa'!$H$4:$H$203,MATCH("Túi mang đi",'Hàng hóa'!$B$4:$B$203,0)),0))} | K18: =IF(A18="","",(H18+I18+J18)*'Thiết lập'!$B$8) | L18: =IF(A18="","",SUM(H18:K18)) | M18: =IF(A18="","",'Thiết lập'!$B$12) | N18: =IF(A18="","",L18+M18) | P18: =IF(AND(D18<>"",O18="Có"),D18,"") | R18: =IF(AND('Hàng hóa'!B30<>"",'Hàng hóa'!C30="Topping",'Hàng hóa'!I30="Có"),'Hàng hóa'!B30,"") | S18: =IF(Size!G19<>"",Size!G19,"")
A19: =IF(OR(B19="",C19=""),"","SP-"&TEXT(ROW()-3,"000")) | D19: =IF(OR(B19="",C19=""),"",B19&" - "&C19) | F19: {=IFERROR(INDEX(Size!$E$4:$E$53,MATCH(C19,Size!$B$4:$B$53,0)),0)} -> 0 | G19: {=IFERROR(INDEX(Size!$C$4:$C$53,MATCH(C19,Size!$B$4:$B$53,0)),0)} -> 0 | H19: =IF(A19="","",G19*'Mẻ sữa'!$U$5) | I19: {=IFERROR(E19*INDEX('Hàng hóa'!$H$4:$H$203,MATCH(B19,'Hàng hóa'!$B$4:$B$203,0)),0)} -> 0 | J19: {=IF(A19="","",IFERROR(INDEX('Hàng hóa'!$H$4:$H$203,MATCH(INDEX(Size!$D$4:$D$53,MATCH(C19,Size!$B$4:$B$53,0)),'Hàng hóa'!$B$4:$B$203,0)),0)+IFERROR(INDEX('Hàng hóa'!$H$4:$H$203,MATCH("Ống hút",'Hàng hóa'!$B$4:$B$203,0)),0)+IFERROR(INDEX('Hàng hóa'!$H$4:$H$203,MATCH("Muỗng",'Hàng hóa'!$B$4:$B$203,0)),0)+IFERROR(INDEX('Hàng hóa'!$H$4:$H$203,MATCH("Túi mang đi",'Hàng hóa'!$B$4:$B$203,0)),0))} | K19: =IF(A19="","",(H19+I19+J19)*'Thiết lập'!$B$8) | L19: =IF(A19="","",SUM(H19:K19)) | M19: =IF(A19="","",'Thiết lập'!$B$12) | N19: =IF(A19="","",L19+M19) | P19: =IF(AND(D19<>"",O19="Có"),D19,"") | R19: =IF(AND('Hàng hóa'!B31<>"",'Hàng hóa'!C31="Topping",'Hàng hóa'!I31="Có"),'Hàng hóa'!B31,"") | S19: =IF(Size!G20<>"",Size!G20,"")
A20: =IF(OR(B20="",C20=""),"","SP-"&TEXT(ROW()-3,"000")) | D20: =IF(OR(B20="",C20=""),"",B20&" - "&C20) | F20: {=IFERROR(INDEX(Size!$E$4:$E$53,MATCH(C20,Size!$B$4:$B$53,0)),0)} -> 0 | G20: {=IFERROR(INDEX(Size!$C$4:$C$53,MATCH(C20,Size!$B$4:$B$53,0)),0)} -> 0 | H20: =IF(A20="","",G20*'Mẻ sữa'!$U$5) | I20: {=IFERROR(E20*INDEX('Hàng hóa'!$H$4:$H$203,MATCH(B20,'Hàng hóa'!$B$4:$B$203,0)),0)} -> 0 | J20: {=IF(A20="","",IFERROR(INDEX('Hàng hóa'!$H$4:$H$203,MATCH(INDEX(Size!$D$4:$D$53,MATCH(C20,Size!$B$4:$B$53,0)),'Hàng hóa'!$B$4:$B$203,0)),0)+IFERROR(INDEX('Hàng hóa'!$H$4:$H$203,MATCH("Ống hút",'Hàng hóa'!$B$4:$B$203,0)),0)+IFERROR(INDEX('Hàng hóa'!$H$4:$H$203,MATCH("Muỗng",'Hàng hóa'!$B$4:$B$203,0)),0)+IFERROR(INDEX('Hàng hóa'!$H$4:$H$203,MATCH("Túi mang đi",'Hàng hóa'!$B$4:$B$203,0)),0))} | K20: =IF(A20="","",(H20+I20+J20)*'Thiết lập'!$B$8) | L20: =IF(A20="","",SUM(H20:K20)) | M20: =IF(A20="","",'Thiết lập'!$B$12) | N20: =IF(A20="","",L20+M20) | P20: =IF(AND(D20<>"",O20="Có"),D20,"") | R20: =IF(AND('Hàng hóa'!B32<>"",'Hàng hóa'!C32="Topping",'Hàng hóa'!I32="Có"),'Hàng hóa'!B32,"") | S20: =IF(Size!G21<>"",Size!G21,"")
A21: =IF(OR(B21="",C21=""),"","SP-"&TEXT(ROW()-3,"000")) | D21: =IF(OR(B21="",C21=""),"",B21&" - "&C21) | F21: {=IFERROR(INDEX(Size!$E$4:$E$53,MATCH(C21,Size!$B$4:$B$53,0)),0)} -> 0 | G21: {=IFERROR(INDEX(Size!$C$4:$C$53,MATCH(C21,Size!$B$4:$B$53,0)),0)} -> 0 | H21: =IF(A21="","",G21*'Mẻ sữa'!$U$5) | I21: {=IFERROR(E21*INDEX('Hàng hóa'!$H$4:$H$203,MATCH(B21,'Hàng hóa'!$B$4:$B$203,0)),0)} -> 0 | J21: {=IF(A21="","",IFERROR(INDEX('Hàng hóa'!$H$4:$H$203,MATCH(INDEX(Size!$D$4:$D$53,MATCH(C21,Size!$B$4:$B$53,0)),'Hàng hóa'!$B$4:$B$203,0)),0)+IFERROR(INDEX('Hàng hóa'!$H$4:$H$203,MATCH("Ống hút",'Hàng hóa'!$B$4:$B$203,0)),0)+IFERROR(INDEX('Hàng hóa'!$H$4:$H$203,MATCH("Muỗng",'Hàng hóa'!$B$4:$B$203,0)),0)+IFERROR(INDEX('Hàng hóa'!$H$4:$H$203,MATCH("Túi mang đi",'Hàng hóa'!$B$4:$B$203,0)),0))} | K21: =IF(A21="","",(H21+I21+J21)*'Thiết lập'!$B$8) | L21: =IF(A21="","",SUM(H21:K21)) | M21: =IF(A21="","",'Thiết lập'!$B$12) | N21: =IF(A21="","",L21+M21) | P21: =IF(AND(D21<>"",O21="Có"),D21,"") | R21: =IF(AND('Hàng hóa'!B33<>"",'Hàng hóa'!C33="Topping",'Hàng hóa'!I33="Có"),'Hàng hóa'!B33,"") | S21: =IF(Size!G22<>"",Size!G22,"")
A22: =IF(OR(B22="",C22=""),"","SP-"&TEXT(ROW()-3,"000")) | D22: =IF(OR(B22="",C22=""),"",B22&" - "&C22) | F22: {=IFERROR(INDEX(Size!$E$4:$E$53,MATCH(C22,Size!$B$4:$B$53,0)),0)} -> 0 | G22: {=IFERROR(INDEX(Size!$C$4:$C$53,MATCH(C22,Size!$B$4:$B$53,0)),0)} -> 0 | H22: =IF(A22="","",G22*'Mẻ sữa'!$U$5) | I22: {=IFERROR(E22*INDEX('Hàng hóa'!$H$4:$H$203,MATCH(B22,'Hàng hóa'!$B$4:$B$203,0)),0)} -> 0 | J22: {=IF(A22="","",IFERROR(INDEX('Hàng hóa'!$H$4:$H$203,MATCH(INDEX(Size!$D$4:$D$53,MATCH(C22,Size!$B$4:$B$53,0)),'Hàng hóa'!$B$4:$B$203,0)),0)+IFERROR(INDEX('Hàng hóa'!$H$4:$H$203,MATCH("Ống hút",'Hàng hóa'!$B$4:$B$203,0)),0)+IFERROR(INDEX('Hàng hóa'!$H$4:$H$203,MATCH("Muỗng",'Hàng hóa'!$B$4:$B$203,0)),0)+IFERROR(INDEX('Hàng hóa'!$H$4:$H$203,MATCH("Túi mang đi",'Hàng hóa'!$B$4:$B$203,0)),0))} | K22: =IF(A22="","",(H22+I22+J22)*'Thiết lập'!$B$8) | L22: =IF(A22="","",SUM(H22:K22)) | M22: =IF(A22="","",'Thiết lập'!$B$12) | N22: =IF(A22="","",L22+M22) | P22: =IF(AND(D22<>"",O22="Có"),D22,"") | R22: =IF(AND('Hàng hóa'!B34<>"",'Hàng hóa'!C34="Topping",'Hàng hóa'!I34="Có"),'Hàng hóa'!B34,"") | S22: =IF(Size!G23<>"",Size!G23,"")
A23: =IF(OR(B23="",C23=""),"","SP-"&TEXT(ROW()-3,"000")) | D23: =IF(OR(B23="",C23=""),"",B23&" - "&C23) | F23: {=IFERROR(INDEX(Size!$E$4:$E$53,MATCH(C23,Size!$B$4:$B$53,0)),0)} -> 0 | G23: {=IFERROR(INDEX(Size!$C$4:$C$53,MATCH(C23,Size!$B$4:$B$53,0)),0)} -> 0 | H23: =IF(A23="","",G23*'Mẻ sữa'!$U$5) | I23: {=IFERROR(E23*INDEX('Hàng hóa'!$H$4:$H$203,MATCH(B23,'Hàng hóa'!$B$4:$B$203,0)),0)} -> 0 | J23: {=IF(A23="","",IFERROR(INDEX('Hàng hóa'!$H$4:$H$203,MATCH(INDEX(Size!$D$4:$D$53,MATCH(C23,Size!$B$4:$B$53,0)),'Hàng hóa'!$B$4:$B$203,0)),0)+IFERROR(INDEX('Hàng hóa'!$H$4:$H$203,MATCH("Ống hút",'Hàng hóa'!$B$4:$B$203,0)),0)+IFERROR(INDEX('Hàng hóa'!$H$4:$H$203,MATCH("Muỗng",'Hàng hóa'!$B$4:$B$203,0)),0)+IFERROR(INDEX('Hàng hóa'!$H$4:$H$203,MATCH("Túi mang đi",'Hàng hóa'!$B$4:$B$203,0)),0))} | K23: =IF(A23="","",(H23+I23+J23)*'Thiết lập'!$B$8) | L23: =IF(A23="","",SUM(H23:K23)) | M23: =IF(A23="","",'Thiết lập'!$B$12) | N23: =IF(A23="","",L23+M23) | P23: =IF(AND(D23<>"",O23="Có"),D23,"") | R23: =IF(AND('Hàng hóa'!B35<>"",'Hàng hóa'!C35="Topping",'Hàng hóa'!I35="Có"),'Hàng hóa'!B35,"") | S23: =IF(Size!G24<>"",Size!G24,"")
A24: =IF(OR(B24="",C24=""),"","SP-"&TEXT(ROW()-3,"000")) | D24: =IF(OR(B24="",C24=""),"",B24&" - "&C24) | F24: {=IFERROR(INDEX(Size!$E$4:$E$53,MATCH(C24,Size!$B$4:$B$53,0)),0)} -> 0 | G24: {=IFERROR(INDEX(Size!$C$4:$C$53,MATCH(C24,Size!$B$4:$B$53,0)),0)} -> 0 | H24: =IF(A24="","",G24*'Mẻ sữa'!$U$5) | I24: {=IFERROR(E24*INDEX('Hàng hóa'!$H$4:$H$203,MATCH(B24,'Hàng hóa'!$B$4:$B$203,0)),0)} -> 0 | J24: {=IF(A24="","",IFERROR(INDEX('Hàng hóa'!$H$4:$H$203,MATCH(INDEX(Size!$D$4:$D$53,MATCH(C24,Size!$B$4:$B$53,0)),'Hàng hóa'!$B$4:$B$203,0)),0)+IFERROR(INDEX('Hàng hóa'!$H$4:$H$203,MATCH("Ống hút",'Hàng hóa'!$B$4:$B$203,0)),0)+IFERROR(INDEX('Hàng hóa'!$H$4:$H$203,MATCH("Muỗng",'Hàng hóa'!$B$4:$B$203,0)),0)+IFERROR(INDEX('Hàng hóa'!$H$4:$H$203,MATCH("Túi mang đi",'Hàng hóa'!$B$4:$B$203,0)),0))} | K24: =IF(A24="","",(H24+I24+J24)*'Thiết lập'!$B$8) | L24: =IF(A24="","",SUM(H24:K24)) | M24: =IF(A24="","",'Thiết lập'!$B$12) | N24: =IF(A24="","",L24+M24) | P24: =IF(AND(D24<>"",O24="Có"),D24,"") | R24: =IF(AND('Hàng hóa'!B36<>"",'Hàng hóa'!C36="Topping",'Hàng hóa'!I36="Có"),'Hàng hóa'!B36,"") | S24: =IF(Size!G25<>"",Size!G25,"")
A25: =IF(OR(B25="",C25=""),"","SP-"&TEXT(ROW()-3,"000")) | D25: =IF(OR(B25="",C25=""),"",B25&" - "&C25) | F25: {=IFERROR(INDEX(Size!$E$4:$E$53,MATCH(C25,Size!$B$4:$B$53,0)),0)} -> 0 | G25: {=IFERROR(INDEX(Size!$C$4:$C$53,MATCH(C25,Size!$B$4:$B$53,0)),0)} -> 0 | H25: =IF(A25="","",G25*'Mẻ sữa'!$U$5) | I25: {=IFERROR(E25*INDEX('Hàng hóa'!$H$4:$H$203,MATCH(B25,'Hàng hóa'!$B$4:$B$203,0)),0)} -> 0 | J25: {=IF(A25="","",IFERROR(INDEX('Hàng hóa'!$H$4:$H$203,MATCH(INDEX(Size!$D$4:$D$53,MATCH(C25,Size!$B$4:$B$53,0)),'Hàng hóa'!$B$4:$B$203,0)),0)+IFERROR(INDEX('Hàng hóa'!$H$4:$H$203,MATCH("Ống hút",'Hàng hóa'!$B$4:$B$203,0)),0)+IFERROR(INDEX('Hàng hóa'!$H$4:$H$203,MATCH("Muỗng",'Hàng hóa'!$B$4:$B$203,0)),0)+IFERROR(INDEX('Hàng hóa'!$H$4:$H$203,MATCH("Túi mang đi",'Hàng hóa'!$B$4:$B$203,0)),0))} | K25: =IF(A25="","",(H25+I25+J25)*'Thiết lập'!$B$8) | L25: =IF(A25="","",SUM(H25:K25)) | M25: =IF(A25="","",'Thiết lập'!$B$12) | N25: =IF(A25="","",L25+M25) | P25: =IF(AND(D25<>"",O25="Có"),D25,"") | R25: =IF(AND('Hàng hóa'!B37<>"",'Hàng hóa'!C37="Topping",'Hàng hóa'!I37="Có"),'Hàng hóa'!B37,"") | S25: =IF(Size!G26<>"",Size!G26,"")
... A52: =IF(OR(B52="",C52=""),"","SP-"&TEXT(ROW()-3,"000")) | D52: =IF(OR(B52="",C52=""),"",B52&" - "&C52) | F52: {=IFERROR(INDEX(Size!$E$4:$E$53,MATCH(C52,Size!$B$4:$B$53,0)),0)} -> 0 | G52: {=IFERROR(INDEX(Size!$C$4:$C$53,MATCH(C52,Size!$B$4:$B$53,0)),0)} -> 0 | H52: =IF(A52="","",G52*'Mẻ sữa'!$U$5) | I52: {=IFERROR(E52*INDEX('Hàng hóa'!$H$4:$H$203,MATCH(B52,'Hàng hóa'!$B$4:$B$203,0)),0)} -> 0 | J52: {=IF(A52="","",IFERROR(INDEX('Hàng hóa'!$H$4:$H$203,MATCH(INDEX(Size!$D$4:$D$53,MATCH(C52,Size!$B$4:$B$53,0)),'Hàng hóa'!$B$4:$B$203,0)),0)+IFERROR(INDEX('Hàng hóa'!$H$4:$H$203,MATCH("Ống hút",'Hàng hóa'!$B$4:$B$203,0)),0)+IFERROR(INDEX('Hàng hóa'!$H$4:$H$203,MATCH("Muỗng",'Hàng hóa'!$B$4:$B$203,0)),0)+IFERROR(INDEX('Hàng hóa'!$H$4:$H$203,MATCH("Túi mang đi",'Hàng hóa'!$B$4:$B$203,0)),0))} | K52: =IF(A52="","",(H52+I52+J52)*'Thiết lập'!$B$8) | L52: =IF(A52="","",SUM(H52:K52)) | M52: =IF(A52="","",'Thiết lập'!$B$12) | N52: =IF(A52="","",L52+M52) | P52: =IF(AND(D52<>"",O52="Có"),D52,"") | R52: =IF(AND('Hàng hóa'!B64<>"",'Hàng hóa'!C64="Topping",'Hàng hóa'!I64="Có"),'Hàng hóa'!B64,"") | S52: =IF(Size!G53<>"",Size!G53,"")
A53: =IF(OR(B53="",C53=""),"","SP-"&TEXT(ROW()-3,"000")) | D53: =IF(OR(B53="",C53=""),"",B53&" - "&C53) | F53: {=IFERROR(INDEX(Size!$E$4:$E$53,MATCH(C53,Size!$B$4:$B$53,0)),0)} -> 0 | G53: {=IFERROR(INDEX(Size!$C$4:$C$53,MATCH(C53,Size!$B$4:$B$53,0)),0)} -> 0 | H53: =IF(A53="","",G53*'Mẻ sữa'!$U$5) | I53: {=IFERROR(E53*INDEX('Hàng hóa'!$H$4:$H$203,MATCH(B53,'Hàng hóa'!$B$4:$B$203,0)),0)} -> 0 | J53: {=IF(A53="","",IFERROR(INDEX('Hàng hóa'!$H$4:$H$203,MATCH(INDEX(Size!$D$4:$D$53,MATCH(C53,Size!$B$4:$B$53,0)),'Hàng hóa'!$B$4:$B$203,0)),0)+IFERROR(INDEX('Hàng hóa'!$H$4:$H$203,MATCH("Ống hút",'Hàng hóa'!$B$4:$B$203,0)),0)+IFERROR(INDEX('Hàng hóa'!$H$4:$H$203,MATCH("Muỗng",'Hàng hóa'!$B$4:$B$203,0)),0)+IFERROR(INDEX('Hàng hóa'!$H$4:$H$203,MATCH("Túi mang đi",'Hàng hóa'!$B$4:$B$203,0)),0))} | K53: =IF(A53="","",(H53+I53+J53)*'Thiết lập'!$B$8) | L53: =IF(A53="","",SUM(H53:K53)) | M53: =IF(A53="","",'Thiết lập'!$B$12) | N53: =IF(A53="","",L53+M53) | P53: =IF(AND(D53<>"",O53="Có"),D53,"") | R53: =IF(AND('Hàng hóa'!B65<>"",'Hàng hóa'!C65="Topping",'Hàng hóa'!I65="Có"),'Hàng hóa'!B65,"")
A54: =IF(OR(B54="",C54=""),"","SP-"&TEXT(ROW()-3,"000")) | D54: =IF(OR(B54="",C54=""),"",B54&" - "&C54) | F54: {=IFERROR(INDEX(Size!$E$4:$E$53,MATCH(C54,Size!$B$4:$B$53,0)),0)} -> 0 | G54: {=IFERROR(INDEX(Size!$C$4:$C$53,MATCH(C54,Size!$B$4:$B$53,0)),0)} -> 0 | H54: =IF(A54="","",G54*'Mẻ sữa'!$U$5) | I54: {=IFERROR(E54*INDEX('Hàng hóa'!$H$4:$H$203,MATCH(B54,'Hàng hóa'!$B$4:$B$203,0)),0)} -> 0 | J54: {=IF(A54="","",IFERROR(INDEX('Hàng hóa'!$H$4:$H$203,MATCH(INDEX(Size!$D$4:$D$53,MATCH(C54,Size!$B$4:$B$53,0)),'Hàng hóa'!$B$4:$B$203,0)),0)+IFERROR(INDEX('Hàng hóa'!$H$4:$H$203,MATCH("Ống hút",'Hàng hóa'!$B$4:$B$203,0)),0)+IFERROR(INDEX('Hàng hóa'!$H$4:$H$203,MATCH("Muỗng",'Hàng hóa'!$B$4:$B$203,0)),0)+IFERROR(INDEX('Hàng hóa'!$H$4:$H$203,MATCH("Túi mang đi",'Hàng hóa'!$B$4:$B$203,0)),0))} | K54: =IF(A54="","",(H54+I54+J54)*'Thiết lập'!$B$8) | L54: =IF(A54="","",SUM(H54:K54)) | M54: =IF(A54="","",'Thiết lập'!$B$12) | N54: =IF(A54="","",L54+M54) | P54: =IF(AND(D54<>"",O54="Có"),D54,"") | R54: =IF(AND('Hàng hóa'!B66<>"",'Hàng hóa'!C66="Topping",'Hàng hóa'!I66="Có"),'Hàng hóa'!B66,"")
A55: =IF(OR(B55="",C55=""),"","SP-"&TEXT(ROW()-3,"000")) | D55: =IF(OR(B55="",C55=""),"",B55&" - "&C55) | F55: {=IFERROR(INDEX(Size!$E$4:$E$53,MATCH(C55,Size!$B$4:$B$53,0)),0)} -> 0 | G55: {=IFERROR(INDEX(Size!$C$4:$C$53,MATCH(C55,Size!$B$4:$B$53,0)),0)} -> 0 | H55: =IF(A55="","",G55*'Mẻ sữa'!$U$5) | I55: {=IFERROR(E55*INDEX('Hàng hóa'!$H$4:$H$203,MATCH(B55,'Hàng hóa'!$B$4:$B$203,0)),0)} -> 0 | J55: {=IF(A55="","",IFERROR(INDEX('Hàng hóa'!$H$4:$H$203,MATCH(INDEX(Size!$D$4:$D$53,MATCH(C55,Size!$B$4:$B$53,0)),'Hàng hóa'!$B$4:$B$203,0)),0)+IFERROR(INDEX('Hàng hóa'!$H$4:$H$203,MATCH("Ống hút",'Hàng hóa'!$B$4:$B$203,0)),0)+IFERROR(INDEX('Hàng hóa'!$H$4:$H$203,MATCH("Muỗng",'Hàng hóa'!$B$4:$B$203,0)),0)+IFERROR(INDEX('Hàng hóa'!$H$4:$H$203,MATCH("Túi mang đi",'Hàng hóa'!$B$4:$B$203,0)),0))} | K55: =IF(A55="","",(H55+I55+J55)*'Thiết lập'!$B$8) | L55: =IF(A55="","",SUM(H55:K55)) | M55: =IF(A55="","",'Thiết lập'!$B$12) | N55: =IF(A55="","",L55+M55) | P55: =IF(AND(D55<>"",O55="Có"),D55,"") | R55: =IF(AND('Hàng hóa'!B67<>"",'Hàng hóa'!C67="Topping",'Hàng hóa'!I67="Có"),'Hàng hóa'!B67,"")
A56: =IF(OR(B56="",C56=""),"","SP-"&TEXT(ROW()-3,"000")) | D56: =IF(OR(B56="",C56=""),"",B56&" - "&C56) | F56: {=IFERROR(INDEX(Size!$E$4:$E$53,MATCH(C56,Size!$B$4:$B$53,0)),0)} -> 0 | G56: {=IFERROR(INDEX(Size!$C$4:$C$53,MATCH(C56,Size!$B$4:$B$53,0)),0)} -> 0 | H56: =IF(A56="","",G56*'Mẻ sữa'!$U$5) | I56: {=IFERROR(E56*INDEX('Hàng hóa'!$H$4:$H$203,MATCH(B56,'Hàng hóa'!$B$4:$B$203,0)),0)} -> 0 | J56: {=IF(A56="","",IFERROR(INDEX('Hàng hóa'!$H$4:$H$203,MATCH(INDEX(Size!$D$4:$D$53,MATCH(C56,Size!$B$4:$B$53,0)),'Hàng hóa'!$B$4:$B$203,0)),0)+IFERROR(INDEX('Hàng hóa'!$H$4:$H$203,MATCH("Ống hút",'Hàng hóa'!$B$4:$B$203,0)),0)+IFERROR(INDEX('Hàng hóa'!$H$4:$H$203,MATCH("Muỗng",'Hàng hóa'!$B$4:$B$203,0)),0)+IFERROR(INDEX('Hàng hóa'!$H$4:$H$203,MATCH("Túi mang đi",'Hàng hóa'!$B$4:$B$203,0)),0))} | K56: =IF(A56="","",(H56+I56+J56)*'Thiết lập'!$B$8) | L56: =IF(A56="","",SUM(H56:K56)) | M56: =IF(A56="","",'Thiết lập'!$B$12) | N56: =IF(A56="","",L56+M56) | P56: =IF(AND(D56<>"",O56="Có"),D56,"") | R56: =IF(AND('Hàng hóa'!B68<>"",'Hàng hóa'!C68="Topping",'Hàng hóa'!I68="Có"),'Hàng hóa'!B68,"")
A57: =IF(OR(B57="",C57=""),"","SP-"&TEXT(ROW()-3,"000")) | D57: =IF(OR(B57="",C57=""),"",B57&" - "&C57) | F57: {=IFERROR(INDEX(Size!$E$4:$E$53,MATCH(C57,Size!$B$4:$B$53,0)),0)} -> 0 | G57: {=IFERROR(INDEX(Size!$C$4:$C$53,MATCH(C57,Size!$B$4:$B$53,0)),0)} -> 0 | H57: =IF(A57="","",G57*'Mẻ sữa'!$U$5) | I57: {=IFERROR(E57*INDEX('Hàng hóa'!$H$4:$H$203,MATCH(B57,'Hàng hóa'!$B$4:$B$203,0)),0)} -> 0 | J57: {=IF(A57="","",IFERROR(INDEX('Hàng hóa'!$H$4:$H$203,MATCH(INDEX(Size!$D$4:$D$53,MATCH(C57,Size!$B$4:$B$53,0)),'Hàng hóa'!$B$4:$B$203,0)),0)+IFERROR(INDEX('Hàng hóa'!$H$4:$H$203,MATCH("Ống hút",'Hàng hóa'!$B$4:$B$203,0)),0)+IFERROR(INDEX('Hàng hóa'!$H$4:$H$203,MATCH("Muỗng",'Hàng hóa'!$B$4:$B$203,0)),0)+IFERROR(INDEX('Hàng hóa'!$H$4:$H$203,MATCH("Túi mang đi",'Hàng hóa'!$B$4:$B$203,0)),0))} | K57: =IF(A57="","",(H57+I57+J57)*'Thiết lập'!$B$8) | L57: =IF(A57="","",SUM(H57:K57)) | M57: =IF(A57="","",'Thiết lập'!$B$12) | N57: =IF(A57="","",L57+M57) | P57: =IF(AND(D57<>"",O57="Có"),D57,"") | R57: =IF(AND('Hàng hóa'!B69<>"",'Hàng hóa'!C69="Topping",'Hàng hóa'!I69="Có"),'Hàng hóa'!B69,"")
A58: =IF(OR(B58="",C58=""),"","SP-"&TEXT(ROW()-3,"000")) | D58: =IF(OR(B58="",C58=""),"",B58&" - "&C58) | F58: {=IFERROR(INDEX(Size!$E$4:$E$53,MATCH(C58,Size!$B$4:$B$53,0)),0)} -> 0 | G58: {=IFERROR(INDEX(Size!$C$4:$C$53,MATCH(C58,Size!$B$4:$B$53,0)),0)} -> 0 | H58: =IF(A58="","",G58*'Mẻ sữa'!$U$5) | I58: {=IFERROR(E58*INDEX('Hàng hóa'!$H$4:$H$203,MATCH(B58,'Hàng hóa'!$B$4:$B$203,0)),0)} -> 0 | J58: {=IF(A58="","",IFERROR(INDEX('Hàng hóa'!$H$4:$H$203,MATCH(INDEX(Size!$D$4:$D$53,MATCH(C58,Size!$B$4:$B$53,0)),'Hàng hóa'!$B$4:$B$203,0)),0)+IFERROR(INDEX('Hàng hóa'!$H$4:$H$203,MATCH("Ống hút",'Hàng hóa'!$B$4:$B$203,0)),0)+IFERROR(INDEX('Hàng hóa'!$H$4:$H$203,MATCH("Muỗng",'Hàng hóa'!$B$4:$B$203,0)),0)+IFERROR(INDEX('Hàng hóa'!$H$4:$H$203,MATCH("Túi mang đi",'Hàng hóa'!$B$4:$B$203,0)),0))} | K58: =IF(A58="","",(H58+I58+J58)*'Thiết lập'!$B$8) | L58: =IF(A58="","",SUM(H58:K58)) | M58: =IF(A58="","",'Thiết lập'!$B$12) | N58: =IF(A58="","",L58+M58) | P58: =IF(AND(D58<>"",O58="Có"),D58,"") | R58: =IF(AND('Hàng hóa'!B70<>"",'Hàng hóa'!C70="Topping",'Hàng hóa'!I70="Có"),'Hàng hóa'!B70,"")
A59: =IF(OR(B59="",C59=""),"","SP-"&TEXT(ROW()-3,"000")) | D59: =IF(OR(B59="",C59=""),"",B59&" - "&C59) | F59: {=IFERROR(INDEX(Size!$E$4:$E$53,MATCH(C59,Size!$B$4:$B$53,0)),0)} -> 0 | G59: {=IFERROR(INDEX(Size!$C$4:$C$53,MATCH(C59,Size!$B$4:$B$53,0)),0)} -> 0 | H59: =IF(A59="","",G59*'Mẻ sữa'!$U$5) | I59: {=IFERROR(E59*INDEX('Hàng hóa'!$H$4:$H$203,MATCH(B59,'Hàng hóa'!$B$4:$B$203,0)),0)} -> 0 | J59: {=IF(A59="","",IFERROR(INDEX('Hàng hóa'!$H$4:$H$203,MATCH(INDEX(Size!$D$4:$D$53,MATCH(C59,Size!$B$4:$B$53,0)),'Hàng hóa'!$B$4:$B$203,0)),0)+IFERROR(INDEX('Hàng hóa'!$H$4:$H$203,MATCH("Ống hút",'Hàng hóa'!$B$4:$B$203,0)),0)+IFERROR(INDEX('Hàng hóa'!$H$4:$H$203,MATCH("Muỗng",'Hàng hóa'!$B$4:$B$203,0)),0)+IFERROR(INDEX('Hàng hóa'!$H$4:$H$203,MATCH("Túi mang đi",'Hàng hóa'!$B$4:$B$203,0)),0))} | K59: =IF(A59="","",(H59+I59+J59)*'Thiết lập'!$B$8) | L59: =IF(A59="","",SUM(H59:K59)) | M59: =IF(A59="","",'Thiết lập'!$B$12) | N59: =IF(A59="","",L59+M59) | P59: =IF(AND(D59<>"",O59="Có"),D59,"") | R59: =IF(AND('Hàng hóa'!B71<>"",'Hàng hóa'!C71="Topping",'Hàng hóa'!I71="Có"),'Hàng hóa'!B71,"")
A60: =IF(OR(B60="",C60=""),"","SP-"&TEXT(ROW()-3,"000")) | D60: =IF(OR(B60="",C60=""),"",B60&" - "&C60) | F60: {=IFERROR(INDEX(Size!$E$4:$E$53,MATCH(C60,Size!$B$4:$B$53,0)),0)} -> 0 | G60: {=IFERROR(INDEX(Size!$C$4:$C$53,MATCH(C60,Size!$B$4:$B$53,0)),0)} -> 0 | H60: =IF(A60="","",G60*'Mẻ sữa'!$U$5) | I60: {=IFERROR(E60*INDEX('Hàng hóa'!$H$4:$H$203,MATCH(B60,'Hàng hóa'!$B$4:$B$203,0)),0)} -> 0 | J60: {=IF(A60="","",IFERROR(INDEX('Hàng hóa'!$H$4:$H$203,MATCH(INDEX(Size!$D$4:$D$53,MATCH(C60,Size!$B$4:$B$53,0)),'Hàng hóa'!$B$4:$B$203,0)),0)+IFERROR(INDEX('Hàng hóa'!$H$4:$H$203,MATCH("Ống hút",'Hàng hóa'!$B$4:$B$203,0)),0)+IFERROR(INDEX('Hàng hóa'!$H$4:$H$203,MATCH("Muỗng",'Hàng hóa'!$B$4:$B$203,0)),0)+IFERROR(INDEX('Hàng hóa'!$H$4:$H$203,MATCH("Túi mang đi",'Hàng hóa'!$B$4:$B$203,0)),0))} | K60: =IF(A60="","",(H60+I60+J60)*'Thiết lập'!$B$8) | L60: =IF(A60="","",SUM(H60:K60)) | M60: =IF(A60="","",'Thiết lập'!$B$12) | N60: =IF(A60="","",L60+M60) | P60: =IF(AND(D60<>"",O60="Có"),D60,"") | R60: =IF(AND('Hàng hóa'!B72<>"",'Hàng hóa'!C72="Topping",'Hàng hóa'!I72="Có"),'Hàng hóa'!B72,"")
A61: =IF(OR(B61="",C61=""),"","SP-"&TEXT(ROW()-3,"000")) | D61: =IF(OR(B61="",C61=""),"",B61&" - "&C61) | F61: {=IFERROR(INDEX(Size!$E$4:$E$53,MATCH(C61,Size!$B$4:$B$53,0)),0)} -> 0 | G61: {=IFERROR(INDEX(Size!$C$4:$C$53,MATCH(C61,Size!$B$4:$B$53,0)),0)} -> 0 | H61: =IF(A61="","",G61*'Mẻ sữa'!$U$5) | I61: {=IFERROR(E61*INDEX('Hàng hóa'!$H$4:$H$203,MATCH(B61,'Hàng hóa'!$B$4:$B$203,0)),0)} -> 0 | J61: {=IF(A61="","",IFERROR(INDEX('Hàng hóa'!$H$4:$H$203,MATCH(INDEX(Size!$D$4:$D$53,MATCH(C61,Size!$B$4:$B$53,0)),'Hàng hóa'!$B$4:$B$203,0)),0)+IFERROR(INDEX('Hàng hóa'!$H$4:$H$203,MATCH("Ống hút",'Hàng hóa'!$B$4:$B$203,0)),0)+IFERROR(INDEX('Hàng hóa'!$H$4:$H$203,MATCH("Muỗng",'Hàng hóa'!$B$4:$B$203,0)),0)+IFERROR(INDEX('Hàng hóa'!$H$4:$H$203,MATCH("Túi mang đi",'Hàng hóa'!$B$4:$B$203,0)),0))} | K61: =IF(A61="","",(H61+I61+J61)*'Thiết lập'!$B$8) | L61: =IF(A61="","",SUM(H61:K61)) | M61: =IF(A61="","",'Thiết lập'!$B$12) | N61: =IF(A61="","",L61+M61) | P61: =IF(AND(D61<>"",O61="Có"),D61,"") | R61: =IF(AND('Hàng hóa'!B73<>"",'Hàng hóa'!C73="Topping",'Hàng hóa'!I73="Có"),'Hàng hóa'!B73,"")
A62: =IF(OR(B62="",C62=""),"","SP-"&TEXT(ROW()-3,"000")) | D62: =IF(OR(B62="",C62=""),"",B62&" - "&C62) | F62: {=IFERROR(INDEX(Size!$E$4:$E$53,MATCH(C62,Size!$B$4:$B$53,0)),0)} -> 0 | G62: {=IFERROR(INDEX(Size!$C$4:$C$53,MATCH(C62,Size!$B$4:$B$53,0)),0)} -> 0 | H62: =IF(A62="","",G62*'Mẻ sữa'!$U$5) | I62: {=IFERROR(E62*INDEX('Hàng hóa'!$H$4:$H$203,MATCH(B62,'Hàng hóa'!$B$4:$B$203,0)),0)} -> 0 | J62: {=IF(A62="","",IFERROR(INDEX('Hàng hóa'!$H$4:$H$203,MATCH(INDEX(Size!$D$4:$D$53,MATCH(C62,Size!$B$4:$B$53,0)),'Hàng hóa'!$B$4:$B$203,0)),0)+IFERROR(INDEX('Hàng hóa'!$H$4:$H$203,MATCH("Ống hút",'Hàng hóa'!$B$4:$B$203,0)),0)+IFERROR(INDEX('Hàng hóa'!$H$4:$H$203,MATCH("Muỗng",'Hàng hóa'!$B$4:$B$203,0)),0)+IFERROR(INDEX('Hàng hóa'!$H$4:$H$203,MATCH("Túi mang đi",'Hàng hóa'!$B$4:$B$203,0)),0))} | K62: =IF(A62="","",(H62+I62+J62)*'Thiết lập'!$B$8) | L62: =IF(A62="","",SUM(H62:K62)) | M62: =IF(A62="","",'Thiết lập'!$B$12) | N62: =IF(A62="","",L62+M62) | P62: =IF(AND(D62<>"",O62="Có"),D62,"") | R62: =IF(AND('Hàng hóa'!B74<>"",'Hàng hóa'!C74="Topping",'Hàng hóa'!I74="Có"),'Hàng hóa'!B74,"")
A63: =IF(OR(B63="",C63=""),"","SP-"&TEXT(ROW()-3,"000")) | D63: =IF(OR(B63="",C63=""),"",B63&" - "&C63) | F63: {=IFERROR(INDEX(Size!$E$4:$E$53,MATCH(C63,Size!$B$4:$B$53,0)),0)} -> 0 | G63: {=IFERROR(INDEX(Size!$C$4:$C$53,MATCH(C63,Size!$B$4:$B$53,0)),0)} -> 0 | H63: =IF(A63="","",G63*'Mẻ sữa'!$U$5) | I63: {=IFERROR(E63*INDEX('Hàng hóa'!$H$4:$H$203,MATCH(B63,'Hàng hóa'!$B$4:$B$203,0)),0)} -> 0 | J63: {=IF(A63="","",IFERROR(INDEX('Hàng hóa'!$H$4:$H$203,MATCH(INDEX(Size!$D$4:$D$53,MATCH(C63,Size!$B$4:$B$53,0)),'Hàng hóa'!$B$4:$B$203,0)),0)+IFERROR(INDEX('Hàng hóa'!$H$4:$H$203,MATCH("Ống hút",'Hàng hóa'!$B$4:$B$203,0)),0)+IFERROR(INDEX('Hàng hóa'!$H$4:$H$203,MATCH("Muỗng",'Hàng hóa'!$B$4:$B$203,0)),0)+IFERROR(INDEX('Hàng hóa'!$H$4:$H$203,MATCH("Túi mang đi",'Hàng hóa'!$B$4:$B$203,0)),0))} | K63: =IF(A63="","",(H63+I63+J63)*'Thiết lập'!$B$8) | L63: =IF(A63="","",SUM(H63:K63)) | M63: =IF(A63="","",'Thiết lập'!$B$12) | N63: =IF(A63="","",L63+M63) | P63: =IF(AND(D63<>"",O63="Có"),D63,"") | R63: =IF(AND('Hàng hóa'!B75<>"",'Hàng hóa'!C75="Topping",'Hàng hóa'!I75="Có"),'Hàng hóa'!B75,"")
A64: =IF(OR(B64="",C64=""),"","SP-"&TEXT(ROW()-3,"000")) | D64: =IF(OR(B64="",C64=""),"",B64&" - "&C64) | F64: {=IFERROR(INDEX(Size!$E$4:$E$53,MATCH(C64,Size!$B$4:$B$53,0)),0)} -> 0 | G64: {=IFERROR(INDEX(Size!$C$4:$C$53,MATCH(C64,Size!$B$4:$B$53,0)),0)} -> 0 | H64: =IF(A64="","",G64*'Mẻ sữa'!$U$5) | I64: {=IFERROR(E64*INDEX('Hàng hóa'!$H$4:$H$203,MATCH(B64,'Hàng hóa'!$B$4:$B$203,0)),0)} -> 0 | J64: {=IF(A64="","",IFERROR(INDEX('Hàng hóa'!$H$4:$H$203,MATCH(INDEX(Size!$D$4:$D$53,MATCH(C64,Size!$B$4:$B$53,0)),'Hàng hóa'!$B$4:$B$203,0)),0)+IFERROR(INDEX('Hàng hóa'!$H$4:$H$203,MATCH("Ống hút",'Hàng hóa'!$B$4:$B$203,0)),0)+IFERROR(INDEX('Hàng hóa'!$H$4:$H$203,MATCH("Muỗng",'Hàng hóa'!$B$4:$B$203,0)),0)+IFERROR(INDEX('Hàng hóa'!$H$4:$H$203,MATCH("Túi mang đi",'Hàng hóa'!$B$4:$B$203,0)),0))} | K64: =IF(A64="","",(H64+I64+J64)*'Thiết lập'!$B$8) | L64: =IF(A64="","",SUM(H64:K64)) | M64: =IF(A64="","",'Thiết lập'!$B$12) | N64: =IF(A64="","",L64+M64) | P64: =IF(AND(D64<>"",O64="Có"),D64,"") | R64: =IF(AND('Hàng hóa'!B76<>"",'Hàng hóa'!C76="Topping",'Hàng hóa'!I76="Có"),'Hàng hóa'!B76,"")
... A103: =IF(OR(B103="",C103=""),"","SP-"&TEXT(ROW()-3,"000")) | D103: =IF(OR(B103="",C103=""),"",B103&" - "&C103) | F103: {=IFERROR(INDEX(Size!$E$4:$E$53,MATCH(C103,Size!$B$4:$B$53,0)),0)} -> 0 | G103: {=IFERROR(INDEX(Size!$C$4:$C$53,MATCH(C103,Size!$B$4:$B$53,0)),0)} -> 0 | H103: =IF(A103="","",G103*'Mẻ sữa'!$U$5) | I103: {=IFERROR(E103*INDEX('Hàng hóa'!$H$4:$H$203,MATCH(B103,'Hàng hóa'!$B$4:$B$203,0)),0)} -> 0 | J103: {=IF(A103="","",IFERROR(INDEX('Hàng hóa'!$H$4:$H$203,MATCH(INDEX(Size!$D$4:$D$53,MATCH(C103,Size!$B$4:$B$53,0)),'Hàng hóa'!$B$4:$B$203,0)),0)+IFERROR(INDEX('Hàng hóa'!$H$4:$H$203,MATCH("Ống hút",'Hàng hóa'!$B$4:$B$203,0)),0)+IFERROR(INDEX('Hàng hóa'!$H$4:$H$203,MATCH("Muỗng",'Hàng hóa'!$B$4:$B$203,0)),0)+IFERROR(INDEX('Hàng hóa'!$H$4:$H$203,MATCH("Túi mang đi",'Hàng hóa'!$B$4:$B$203,0)),0))} | K103: =IF(A103="","",(H103+I103+J103)*'Thiết lập'!$B$8) | L103: =IF(A103="","",SUM(H103:K103)) | M103: =IF(A103="","",'Thiết lập'!$B$12) | N103: =IF(A103="","",L103+M103) | P103: =IF(AND(D103<>"",O103="Có"),D103,"") | R103: =IF(AND('Hàng hóa'!B115<>"",'Hàng hóa'!C115="Topping",'Hàng hóa'!I115="Có"),'Hàng hóa'!B115,"")
R104: =IF(AND('Hàng hóa'!B116<>"",'Hàng hóa'!C116="Topping",'Hàng hóa'!I116="Có"),'Hàng hóa'!B116,"")
...

Sheet Hàng hóa
A1: DANH MỤC HÀNG HÓA — NHẬP TIẾP XUỐNG DƯỚI
A2: Có sẵn 200 dòng. Khi thêm nguyên liệu/topping/bao bì mới, chỉ nhập vào dòng trống tiếp theo. | M2: Nhóm | N2: Kích hoạt | O2: Đơn vị
A3: Mã nội bộ | B3: Tên hàng | C3: Nhóm | D3: Đơn vị mua | E3: Quy cách/gói | F3: Đơn vị tính cost | G3: Giá tham khảo/gói (đ) | H3: Giá vốn BQ/đơn vị (đ) | I3: Kích hoạt | J3: Ghi chú | K3: DS tên hàng | M3: Nguyên liệu | N3: Có | O3: lít
A4: NL001 | B4: Sữa tươi | C4: Nguyên liệu | D4: Bịch | E4: 1 | F4: lít | G4: 25000 | H4: =IF(B4="","",IFERROR(IF(SUMIFS('Nhập hàng'!$J$4:$J$503,'Nhập hàng'!$C$4:$C$503,A4)>0,SUMIFS('Nhập hàng'!$K$4:$K$503,'Nhập hàng'!$C$4:$C$503,A4)/SUMIFS('Nhập hàng'!$J$4:$J$503,'Nhập hàng'!$C$4:$C$503,A4),G4/E4),0)) -> 24250 | I4: Có | J4: 25.000đ/lít | K4: =IF(AND(B4<>"",I4="Có"),B4,"") -> Sữa tươi | M4: Topping | N4: Không | O4: ml
A5: NL002 | B5: Whipping cream | C5: Nguyên liệu | D5: Hộp | E5: 1 | F5: lít | G5: 158000 | H5: =IF(B5="","",IFERROR(IF(SUMIFS('Nhập hàng'!$J$4:$J$503,'Nhập hàng'!$C$4:$C$503,A5)>0,SUMIFS('Nhập hàng'!$K$4:$K$503,'Nhập hàng'!$C$4:$C$503,A5)/SUMIFS('Nhập hàng'!$J$4:$J$503,'Nhập hàng'!$C$4:$C$503,A5),G5/E5),0)) -> 79000 | I5: Có | J5: 1 hộp = 1.000ml | K5: =IF(AND(B5<>"",I5="Có"),B5,"") -> Whipping cream | M5: Bao bì | O5: kg
A6: NL003 | B6: Đường | C6: Nguyên liệu | D6: Bịch | E6: 1 | F6: kg | G6: 22000 | H6: =IF(B6="","",IFERROR(IF(SUMIFS('Nhập hàng'!$J$4:$J$503,'Nhập hàng'!$C$4:$C$503,A6)>0,SUMIFS('Nhập hàng'!$K$4:$K$503,'Nhập hàng'!$C$4:$C$503,A6)/SUMIFS('Nhập hàng'!$J$4:$J$503,'Nhập hàng'!$C$4:$C$503,A6),G6/E6),0)) -> 25333.333 | I6: Có | K6: =IF(AND(B6<>"",I6="Có"),B6,"") -> Đường | O6: gram
A7: BB001 | B7: Ly size M | C7: Bao bì | D7: Lốc | E7: 50 | F7: cái | G7: 15000 | H7: =IF(B7="","",IFERROR(IF(SUMIFS('Nhập hàng'!$J$4:$J$503,'Nhập hàng'!$C$4:$C$503,A7)>0,SUMIFS('Nhập hàng'!$K$4:$K$503,'Nhập hàng'!$C$4:$C$503,A7)/SUMIFS('Nhập hàng'!$J$4:$J$503,'Nhập hàng'!$C$4:$C$503,A7),G7/E7),0)) -> 300 | I7: Có | J7: Chưa có giá riêng | K7: =IF(AND(B7<>"",I7="Có"),B7,"") -> Ly size M | O7: cái
A8: BB002 | B8: Nắp size M | C8: Bao bì | D8: Bịch | E8: 50 | F8: cái | G8: 12000 | H8: =IF(B8="","",IFERROR(IF(SUMIFS('Nhập hàng'!$J$4:$J$503,'Nhập hàng'!$C$4:$C$503,A8)>0,SUMIFS('Nhập hàng'!$K$4:$K$503,'Nhập hàng'!$C$4:$C$503,A8)/SUMIFS('Nhập hàng'!$J$4:$J$503,'Nhập hàng'!$C$4:$C$503,A8),G8/E8),0)) -> 240 | I8: Có | J8: Chưa có giá riêng | K8: =IF(AND(B8<>"",I8="Có"),B8,"") -> Nắp size M | O8: cuộn
A9: BB003 | B9: Ly size L | C9: Bao bì | D9: Lốc | E9: 50 | F9: cái | G9: 22000 | H9: =IF(B9="","",IFERROR(IF(SUMIFS('Nhập hàng'!$J$4:$J$503,'Nhập hàng'!$C$4:$C$503,A9)>0,SUMIFS('Nhập hàng'!$K$4:$K$503,'Nhập hàng'!$C$4:$C$503,A9)/SUMIFS('Nhập hàng'!$J$4:$J$503,'Nhập hàng'!$C$4:$C$503,A9),G9/E9),0)) -> 300 | I9: Có | J9: Chưa có giá riêng | K9: =IF(AND(B9<>"",I9="Có"),B9,"") -> Ly size L | O9: khác
A10: BB004 | B10: Nắp size L | C10: Bao bì | D10: Bịch | E10: 50 | F10: cái | G10: 12000 | H10: =IF(B10="","",IFERROR(IF(SUMIFS('Nhập hàng'!$J$4:$J$503,'Nhập hàng'!$C$4:$C$503,A10)>0,SUMIFS('Nhập hàng'!$K$4:$K$503,'Nhập hàng'!$C$4:$C$503,A10)/SUMIFS('Nhập hàng'!$J$4:$J$503,'Nhập hàng'!$C$4:$C$503,A10),G10/E10),0)) -> 240 | I10: Có | J10: Chưa có giá riêng | K10: =IF(AND(B10<>"",I10="Có"),B10,"") -> Nắp size L
A11: BB005 | B11: Ống hút | C11: Bao bì | D11: Bịch | E11: 100 | F11: cái | G11: 25000 | H11: =IF(B11="","",IFERROR(IF(SUMIFS('Nhập hàng'!$J$4:$J$503,'Nhập hàng'!$C$4:$C$503,A11)>0,SUMIFS('Nhập hàng'!$K$4:$K$503,'Nhập hàng'!$C$4:$C$503,A11)/SUMIFS('Nhập hàng'!$J$4:$J$503,'Nhập hàng'!$C$4:$C$503,A11),G11/E11),0)) -> 250 | I11: Có | J11: 1 cái/ly | K11: =IF(AND(B11<>"",I11="Có"),B11,"") -> Ống hút
A12: BB006 | B12: Muỗng | C12: Bao bì | D12: Bịch | E12: 100 | F12: cái | G12: 11000 | H12: =IF(B12="","",IFERROR(IF(SUMIFS('Nhập hàng'!$J$4:$J$503,'Nhập hàng'!$C$4:$C$503,A12)>0,SUMIFS('Nhập hàng'!$K$4:$K$503,'Nhập hàng'!$C$4:$C$503,A12)/SUMIFS('Nhập hàng'!$J$4:$J$503,'Nhập hàng'!$C$4:$C$503,A12),G12/E12),0)) -> 110 | I12: Có | J12: 1 cái/ly | K12: =IF(AND(B12<>"",I12="Có"),B12,"") -> Muỗng
